Workbook

Sheet SUM
B2: 1 | E2: 2 | H2: 3 | K2: 4 | N2: 5 | Q2: 6 | T2: 7 | W2: 8 | Z2: 9 | AC2: 10 | AF2: 11 | AI2: 12
B4: 6 | C4: ='06012025'!D$1 -> 125 | E4: 3 | F4: ='03022025'!$D$1 -> 61 | H4: 3 | I4: ='03032025'!$D$1 -> 112 | K4: 3 | L4: ='03042025'!$D$1 -> 155 | N4: 5 | O4: ='05052025'!$D$1 -> 122 | Q4: 2 | R4: ='02062025'!$D$1 -> 108 | T4: 3 | U4: ='03072025'!$D$1 -> 72 | W4: 4 | X4: ='04082025'!$D$1 -> 101 | Z4: 1 | AA4: ='01092025'!$D$1 -> 133 | AC4: 2 | AD4: ='2102025'!$D$1 -> 147 | AF4: 3 | AG4: ='3112025'!$D$1 -> 110 | AI4: 1
B5: 9 | C5: ='09012025'!D$1 -> 161 | E5: 6 | F5: ='06022025'!D$1 -> 82 | H5: 6 | I5: ='06032025'!$D$1 -> 159 | K5: 7 | L5: ='07042025'!$D$1 -> 81 | N5: 8 | O5: ='08052025'!$D$1 -> 130 | Q5: 5 | R5: ='05062025'!$D$1 -> 145 | T5: 7 | U5: ='07072025'!$D$1 -> 109 | W5: 7 | X5: ='07082025'!$D$1 -> 94 | Z5: 4 | AA5: ='04092025'!$D$1 -> 117 | AC5: 6 | AD5: ='6102025'!$D$1 -> 104 | AF5: 6 | AG5: ='6112025'!$D$1 -> 139 | AI5: 4
B6: 13 | C6: ='13012025'!D$1 -> 95 | E6: 10 | F6: ='10022025'!D$1 -> 80 | H6: 10 | I6: ='10032025'!$D$1 -> 74 | K6: 10 | L6: ='10042025'!$D$1 -> 95 | N6: 12 | O6: ='12052025'!$D$1 -> 91 | Q6: 9 | R6: ='09062025'!$D$1 -> 62 | T6: 10 | U6: ='10072025'!$D$1 -> 129 | W6: 11 | X6: ='11082025'!$D$1 -> 82 | Z6: 8 | AA6: ='08092025'!$D$1 -> 120 | AC6: 9 | AD6: ='9102025'!$D$1 -> 133 | AF6: 10 | AG6: ='10112025'!$D$1 -> 0 | AI6: 8
B7: 16 | C7: ='16012025'!D$1 -> 102 | E7: 13 | F7: ='03022025'!D$1 -> 61 | H7: 13 | I7: ='13032025'!$D$1 -> 96 | K7: 17 | L7: ='17042025'!$D$1 -> 121 | N7: 15 | O7: ='15052025'!$D$1 -> 105 | Q7: 12 | R7: ='12062025'!$D$1 -> 93 | T7: 14 | U7: ='14072025'!$D$1 -> 103 | W7: 14 | X7: ='14082025'!$D$1 -> 80 | Z7: 11 | AA7: ='11092025'!$D$1 -> 84 | AC7: 13 | AD7: ='13102025'!$D$1 -> 105 | AF7: 13 | AG7: ='13112025'!$D$1 -> 0 | AI7: 11
B8: 20 | C8: ='20012025'!D$1 -> 79 | E8: 17 | F8: ='17022025'!D$1 -> 85 | H8: 17 | I8: ='17032025'!$D$1 -> 59 | K8: 21 | L8: ='21042025'!$D$1 -> 119 | N8: 19 | O8: ='19052025'!$D$1 -> 73 | Q8: 16 | R8: ='16062025'!$D$1 -> 74 | T8: 17 | U8: ='17072025'!$D$1 -> 117 | W8: 18 | X8: ='18082025'!$D$1 -> 96 | Z8: 15 | AA8: ='15092025'!$D$1 -> 85 | AC8: 16 | AD8: ='16102025'!$D$1 -> 76 | AF8: 17 | AG8: ='17112025'!$D$1 -> 0 | AI8: 15
B9: 23 | C9: ='23012025'!D$1 -> 92 | E9: 20 | F9: ='20022025'!D$1 -> 92 | H9: 20 | I9: ='20032025'!$D$1 -> 98 | K9: 24 | L9: ='24042025'!$D$1 -> 106 | N9: 22 | O9: ='22052025'!$D$1 -> 106 | Q9: 19 | R9: ='19062025'!$D$1 -> 95 | T9: 21 | U9: ='21072025'!$D$1 -> 92 | W9: 21 | X9: ='21082025'!$D$1 -> 66 | Z9: 17 | AA9: ='17092025'!$D$1 -> 2 | AC9: 20 | AD9: ='20102025'!$D$1 -> 132 | AF9: 20 | AG9: ='20112025'!$D$1 -> 0 | AI9: 18
B10: 27 | C10: ='27012025'!D$1 -> 72 | E10: 24 | F10: ='24022025'!D$1 -> 58 | H10: 24 | I10: ='24032025'!$D$1 -> 119 | K10: 28 | L10: ='28042025'!$D$1 -> 140 | N10: 26 | O10: ='26052025'!$D$1 -> 87 | Q10: 23 | R10: ='23062025'!$D$1 -> 116 | T10: 24 | U10: ='24072025'!$D$1 -> 65 | W10: 25 | X10: ='25082025'!$D$1 -> 92 | Z10: 22 | AA10: ='22092025'!$D$1 -> 99 | AC10: 23 | AD10: ='23102025'!$D$1 -> 118 | AF10: 24 | AG10: ='24112025'!$D$1 -> 0 | AI10: 22
B11: 30 | C11: ='30012025'!D$1 -> 108 | E11: 27 | F11: ='27022025'!D$1 -> 155 | H11: 27 | I11: ='27032025'!$D$1 -> 99 | N11: 29 | O11: ='29052025'!$D$1 -> 93 | Q11: 26 | R11: ='26062025'!$D$1 -> 106 | T11: 28 | U11: ='28072025'!$D$1 -> 98 | W11: 28 | X11: ='28082025'!$D$1 -> 134 | Z11: 25 | AA11: ='25092025'!$D$1 -> 103 | AC11: 27 | AD11: ='27102025'!$D$1 -> 107 | AF11: 27 | AG11: ='27112025'!$D$1 -> 0 | AI11: 25
H12: 31 | I12: ='31032025'!$D$1 -> 69 | Q12: 30 | R12: ='30062025'!$D$1 -> 104 | T12: 31 | U12: ='31072025'!$D$1 -> 99 | Z12: 29 | AA12: ='29092025'!$D$1 -> 105 | AC12: 30 | AD12: ='30102025'!$D$1 -> 89 | AI12: 29
B14: =COUNTA(B4:B13) -> 8 | C14: =SUM(C4:C13) -> 834 | E14: =COUNTA(E4:E13) -> 8 | F14: =SUM(F4:F13) -> 674 | H14: =COUNTA(H4:H13) -> 9 | I14: =SUM(I4:I13) -> 885 | K14: =COUNTA(K4:K13) -> 7 | L14: =SUM(L4:L13) -> 817 | N14: =COUNTA(N4:N13) -> 8 | O14: =SUM(O4:O13) -> 807 | Q14: =COUNTA(Q4:Q13) -> 9 | R14: =SUM(R4:R13) -> 903 | T14: =COUNTA(T4:T13) -> 9 | U14: =SUM(U4:U13) -> 884 | W14: =COUNTA(W4:W13) -> 8 | X14: =SUM(X4:X13) -> 745 | Z14: =COUNTA(Z4:Z13) -> 9 | AA14: =SUM(AA4:AA13) -> 848 | AC14: =COUNTA(AC4:AC13) -> 9 | AD14: =SUM(AD4:AD13) -> 1011 | AF14: =COUNTA(AF4:AF13) -> 8 | AG14: =SUM(AG4:AG13) -> 249 | AI14: =COUNTA(AI4:AI13) -> 9 | AJ14: =SUM(AJ4:AJ13) -> 0
B16: =SUM(B14,E14,H14,K14,N14,Q14,T14,W14,Z14,AC14,AF14,AI14) -> 101
B17: =SUM(C14,F14,I14,L14,O14,R14,U14,X14,AA14,AD14,AG14,AJ14) -> 8657

Sheet 06012025
C1: 45663 | D1: 125 | E1: =COUNTA(B:B)-1 -> 125
A2: รูปภาพ | B2: ลำดับที่ | C2: ยี่ห้อ | D2: รุ่น | E2: ประเภทรถกระบะ | F2: รุ่นย่อย | G2: เกรด | H2: ราคาเริ่มต้น (ไม่รวมvat) | I2: ค่าธรรมเนียม (ไม่รวมvat) | J2: ราคาสูงสุด | K2: ปีที่ผลิต | L2: ป้ายทะเบียนรถ | M2: จังหวัด | N2: ปีที่จดทะเบียน | O2: เลขไมล์ (กม.) | P2: ระบบขับเคลื่อน | Q2: ความจุ (CC) | R2: สี | S2: ระบบเกียร์ | T2: เชื้อเพลิง | U2: สถานที่จอดรถ | V2: ประเภทรถประมูล
B3: 1001 | C3: Toyota | D3: Corolla Cross | F3: HEV GR Sport | G3: A | H3: 760000 | I3: 17400 | J3: 844000 | K3: 2023 | L3: ขย-2165 | M3: ระยอง | N3: 2023 | O3: 56269 | P3: FWD | Q3: 1.8 | R3: ขาว ดำ | S3: AT | T3: ไฮบริด | U3: สุวินทวงศ์ | V3: ถูกยึดคืน
C4: หมายเหตุ: ค่าเช็คต้น 100 บาท ภาษีหมดอายุ 17-02-25 ผู้ซื้อต้องดำเนินการต่อภาษีเอง กรณีไม่มีป้ายภาษี ผู้ซื้อต้องรับผิดชอบคัดป้ายใหม่เอง กรณีรถติดอายัดจราจร หรือ มีค่าใช้จ่ายคงค้างจากการใช้ทางด่วน/M-flow ผู้ซื้อเป็นผู้รับผิดชอบค่าใช้จ่ายทุกกรณี
B5: 1002 | C5: Toyota | D5: Hilux Revo | E5: Double Cab | F5: Z Edition Mid | G5: C | H5: 340000 | I5: 19600 | J5: 458000 | K5: 2023 | L5: จต-6992 | M5: เชียงใหม่ | N5: 2023 | O5: 14572 | P5: RWD | Q5: 2.4 | R5: ขาว | S5: AT | T5: ดีเซล | U5: สุวินทวงศ์ | V5: ถูกยึดคืน
C6: หมายเหตุ: ค่าเช็คต้น 100 บาท ภาษีหมดอายุ 19-07-24 ผู้ซื้อต้องดำเนินการต่อภาษีเอง กรณีไม่มีป้ายภาษี ผู้ซื้อต้องรับผิดชอบคัดป้ายใหม่เอง กรณีรถติดอายัดจราจร หรือ มีค่าใช้จ่ายคงค้างจากการใช้ทางด่วน/M-flow ผู้ซื้อเป็นผู้รับผิดชอบค่าใช้จ่ายทุกกรณี
B7: 1003 | C7: Toyota | D7: Yaris Ativ | F7: Sport | G7: B | H7: 240000 | I7: 17400 | J7: 296000 | K7: 2021 | L7: 3ขญ-1687 | M7: กรุงเทพมหานคร | N7: 2022 | O7: 36878 | P7: FWD | Q7: 1.2 | R7: ขาว | S7: AT | T7: เบนซิน | U7: สุวินทวงศ์ | V7: ถูกยึดคืน
C8: หมายเหตุ: ค่าเช็คต้น 100 บาท ภาษีหมดอายุ 17-08-24 ผู้ซื้อต้องดำเนินการต่อภาษีเอง กรณีไม่มีป้ายภาษี ผู้ซื้อต้องรับผิดชอบคัดป้ายใหม่เอง กรณีรถติดอายัดจราจร หรือ มีค่าใช้จ่ายคงค้างจากการใช้ทางด่วน/M-flow ผู้ซื้อเป็นผู้รับผิดชอบค่าใช้จ่ายทุกกรณี
B9: 1004 | C9: Toyota | D9: Corolla Altis | F9: Hybrid Premium Safety | G9: A | H9: 420000 | I9: 19600 | J9: 548000 | K9: 2019 | L9: ขม-6569 | M9: ขอนแก่น | N9: 2019 | O9: 42038 | P9: FWD | Q9: 1.8 | R9: ดำ | S9: AT | T9: ไฮบริด | U9: สุวินทวงศ์ | V9: ถูกยึดคืน
C10: หมายเหตุ: ค่าเช็คต้น 100 บาท ภาษีหมดอายุ 16-12-25 ผู้ซื้อต้องดำเนินการต่อภาษีเอง กรณีไม่มีป้ายภาษี ผู้ซื้อต้องรับผิดชอบคัดป้ายใหม่เอง กรณีรถติดอายัดจราจร หรือ มีค่าใช้จ่ายคงค้างจากการใช้ทางด่วน/M-flow ผู้ซื้อเป็นผู้รับผิดชอบค่าใช้จ่ายทุกกรณี
B11: 1005 | C11: Toyota | D11: Hilux Revo | E11: Double Cab | F11: Prerunner E Plus | G11: C | H11: 300000 | I11: 20400 | J11: 344000 | K11: 2018 | L11: 7กฎ-9142 | M11: กรุงเทพมหานคร | N11: 2018 | O11: 103821 | P11: RWD | Q11: 2.4 | R11: ดำ | S11: MT | T11: ดีเซล | U11: สุวินทวงศ์ | V11: ถูกยึดคืน
C12: หมายเหตุ: ค่าเช็คต้น 100 บาท ภาษีหมดอายุ 27-03-24 ผู้ซื้อต้องดำเนินการต่อภาษีเอง กรณีไม่มีป้ายภาษี ผู้ซื้อต้องรับผิดชอบคัดป้ายใหม่เอง กรณีรถติดอายัดจราจร หรือ มีค่าใช้จ่ายคงค้างจากการใช้ทางด่วน/M-flow ผู้ซื้อเป็นผู้รับผิดชอบค่าใช้จ่ายทุกกรณี
B13: 1006 | C13: Toyota | D13: Hilux Revo | E13: Smart Cab | F13: Prerunner Entry | G13: S | H13: 410000 | I13: 20600 | J13: 446000 | K13: 2024 | L13: 3ฒอ-9319 | M13: กรุงเทพมหานคร | N13: 2024 | O13: 5860 | P13: RWD | Q13: 2.4 | R13: เทา | S13: MT | T13: ดีเซล | U13: สุวินทวงศ์ | V13: ถูกยึดคืน
C14: หมายเหตุ: ค่าเช็คต้น 100 บาท ภาษีหมดอายุ 17-05-25 ผู้ซื้อต้องดำเนินการต่อภาษีเอง กรณีไม่มีป้ายภาษี ผู้ซื้อต้องรับผิดชอบคัดป้ายใหม่เอง กรณีรถติดอายัดจราจร หรือ มีค่าใช้จ่ายคงค้างจากการใช้ทางด่วน/M-flow ผู้ซื้อเป็นผู้รับผิดชอบค่าใช้จ่ายทุกกรณี
B15: 1007 | C15: Toyota | D15: Fortuner | F15: Legender | G15: A | H15: 950000 | I15: 18900 | J15: 1195000 | K15: 2022 | L15: งบ-7724 | M15: นครราชสีมา | N15: 2022 | O15: 43946 | P15: 4WD | Q15: 2.8 | R15: ขาว ดำ | S15: AT | T15: ดีเซล | U15: สุวินทวงศ์ | V15: ถูกยึดคืน
C16: หมายเหตุ: ค่าเช็คต้น 100 บาท ภาษีหมดอายุ 18-08-24 ผู้ซื้อต้องดำเนินการต่อภาษีเอง กรณีไม่มีป้ายภาษี ผู้ซื้อต้องรับผิดชอบคัดป้ายใหม่เอง กรณีรถติดอายัดจราจร หรือ มีค่าใช้จ่ายคงค้างจากการใช้ทางด่วน/M-flow ผู้ซื้อเป็นผู้รับผิดชอบค่าใช้จ่ายทุกกรณี
B17: 1008 | C17: Toyota | D17: Hilux Revo | E17: Double Cab | F17: Prerunner Mid | G17: A | H17: 460000 | I17: 20100 | J17: 534000 | K17: 2022 | L17: กฉ-5297 | M17: มุกดาหาร | N17: 2023 | O17: 26474 | P17: RWD | Q17: 2.4 | R17: เทา | S17: MT | T17: ดีเซล | U17: สุวินทวงศ์ | V17: ถูกยึดคืน
C18: หมายเหตุ: ค่าเช็คต้น 100 บาท ภาษีหมดอายุ 28-02-24 ผู้ซื้อต้องดำเนินการต่อภาษีเอง กรณีไม่มีป้ายภาษี ผู้ซื้อต้องรับผิดชอบคัดป้ายใหม่เอง กรณีรถติดอายัดจราจร หรือ มีค่าใช้จ่ายคงค้างจากการใช้ทางด่วน/M-flow ผู้ซื้อเป็นผู้รับผิดชอบค่าใช้จ่ายทุกกรณี
B19: 1009 | C19: Toyota | D19: Hilux Revo | E19: Smart Cab | F19: Z Edition Entry | G19: A | H19: 242000 | I19: 19600 | J19: 334000 | K19: 2023 | L19: ยค-9806 | M19: ขอนแก่น | N19: 2024 | O19: 2029 | P19: RWD | Q19: 2.4 | R19: เทา | S19: MT | T19: ดีเซล | U19: สุวินทวงศ์ | V19: ถูกยึดคืน
C20: หมายเหตุ: ค่าเช็คต้น 100 บาท ภาษีหมดอายุ 18-03-25 ผู้ซื้อต้องดำเนินการต่อภาษีเอง กรณีไม่มีป้ายภาษี ผู้ซื้อต้องรับผิดชอบคัดป้ายใหม่เอง กรณีรถติดอายัดจราจร หรือ มีค่าใช้จ่ายคงค้างจากการใช้ทางด่วน/M-flow ผู้ซื้อเป็นผู้รับผิดชอบค่าใช้จ่ายทุกกรณี
B21: 1010 | C21: Toyota | D21: Hilux Revo | E21: Smart Cab | F21: Entry | G21: B | H21: 230000 | I21: 19600 | J21: 282000 | K21: 2022 | L21: ผบ-1231 | M21: อุบลราชธานี | N21: 2022 | O21: 64072 | P21: RWD | Q21: 2.4 | R21: เทา | S21: MT | T21: ดีเซล | U21: สุวินทวงศ์ | V21: ถูกยึดคืน
C22: หมายเหตุ: ค่าเช็คต้น 100 บาท ภาษีหมดอายุ 26-05-25 ผู้ซื้อต้องดำเนินการต่อภาษีเอง กรณีไม่มีป้ายภาษี ผู้ซื้อต้องรับผิดชอบคัดป้ายใหม่เอง กรณีรถติดอายัดจราจร หรือ มีค่าใช้จ่ายคงค้างจากการใช้ทางด่วน/M-flow ผู้ซื้อเป็นผู้รับผิดชอบค่าใช้จ่ายทุกกรณี
B23: 1011 | C23: Mitsubishi | D23: Triton | E23: Smart Cab | F23: GLX | G23: A | H23: 220000 | I23: 10000 | J23: 288000 | K23: 2022 | L23: ผธ-8509 | M23: เชียงราย | N23: 2023 | O23: 14340 | P23: RWD | Q23: 2.5 | R23: ดำ | S23: MT | T23: ดีเซล | U23: สุวินทวงศ์
C24: หมายเหตุ: (KA) กรณีเอกสารหมดอายุหรือสูญหาย ขอเอกสารใหม่มีค่าใช้จ่าย 500 บาท
B25: 1012 | C25: Isuzu | D25: D-Max | E25: Double Cab | F25: Hi-Lander Z | G25: E | H25: 210000 | I25: 10000 | J25: 312000 | K25: 2016 | L25: 5กฒ-7363 | M25: กรุงเทพมหานคร | N25: 2016 | O25: 190015 | P25: RWD | Q25: 1.9 | R25: เทา | S25: MT | T25: ดีเซล | U25: สุวินทวงศ์
C26: หมายเหตุ: มีค่าปรับ M-flow 330 บาท กรณีเอกสารหมดอายุหรือสูญหาย ขอเอกสารใหม่มีค่าใช้จ่าย 500 บาท
B27: 1013 | C27: Toyota | D27: Camry | F27: Hybrid | G27: C | H27: 100000 | I27: 10000 | J27: 150000 | K27: 2011 | L27: กฉ-7525 | M27: นครพนม | N27: 2014 | O27: 257655 | P27: FWD | Q27: 2.4 | R27: ขาว | S27: AT | T27: ไฮบริด | U27: สุวินทวงศ์
C28: หมายเหตุ: รถติดอายัดจราจร มีใบสั่ง 3 ใบ ปรับ 1500 บาท กรณีเอกสารหมดอายุหรือสูญหาย ขอเอกสารใหม่มีค่าใช้จ่าย 500 บาท
B29: 1014 | C29: Toyota | D29: Fortuner | F29: V | G29: E | H29: 220000 | I29: 10000 | J29: 234000 | K29: 2008 | L29: ชฬ-521 | M29: กรุงเทพมหานคร | N29: 2008 | O29: 336973 | P29: 4WD | Q29: 3 | R29: ดำ | S29: AT | T29: ดีเซล | U29: สุวินทวงศ์
C30: หมายเหตุ: ออกใบแทนคู่มือทะเบียนใหม่ กรณีรายการต่อเต็ม กรณีเอกสารหมดอายุหรือสูญหาย ขอเอกสารใหม่มีค่าใช้จ่าย 500 บาท
B31: 1015 | C31: Toyota | D31: Hilux Revo | E31: Single Cab | F31: Entry | G31: E | H31: 160000 | I31: 10000 | J31: 218000 | K31: 2020 | L31: 3ฒจ-9198 | M31: กรุงเทพมหานคร | N31: 2021 | O31: 190177 | P31: RWD | Q31: 2.4 | R31: ขาว | S31: MT | T31: ดีเซล | U31: สุวินทวงศ์
C32: หมายเหตุ: กรณีเอกสารหมดอายุหรือสูญหาย ขอเอกสารใหม่มีค่าใช้จ่าย 500 บาท
B33: 1016 | C33: Mitsubishi | D33: Attrage | F33: GLX | G33: E | H33: 140000 | I33: 10000 | J33: 140000 | K33: 2020 | L33: ขข-6001 | M33: อุบลราชธานี | N33: 2021 | O33: 144318 | P33: FWD | Q33: 1.2 | R33: ขาว | S33: AT | T33: เบนซิน | U33: สุวินทวงศ์
C34: หมายเหตุ: มีค่าปรับ M-FLOW 990 บาท รถติดอายัดจราจร มีใบสั่ง 1 ใบ ปรับ 500 บาท กรณีเอกสารหมดอายุหรือสูญหาย ขอเอกสารใหม่มีค่าใช้จ่าย 500 บาท
B35: 1017 | C35: Isuzu | D35: D-Max | E35: Extra Cab | F35: SLX Super Titanium | G35: F | H35: 70000 | I35: 10000 | J35: 78000 | K35: 2011 | L35: ผย-6782 | M35: ชลบุรี | N35: 2011 | O35: 109287 | P35: RWD | Q35: 2.5 | R35: เทา | S35: MT | T35: ดีเซล | U35: สุวินทวงศ์
C36: หมายเหตุ: ไม่รับผิดชอบการโอนทุกกรณี เนื่องจากรถมีการดัดแปลงเว้าโครงแซสซี เรือนไมล์ชำรุด ขายตามสภาพ กรณีเอกสารหมดอายุหรือสูญหาย ขอเอกสารใหม่มีค่าใช้จ่าย 500 บาท
B37: 1018 | C37: Honda | D37: Civic | F37: E i-VTEC | G37: F | H37: 60000 | I37: 10000 | J37: 92000 | K37: 2006 | L37: ขค-1239 | M37: พิษณุโลก | N37: 2007 | O37: 185501 | P37: FWD | Q37: 2 | R37: เทา | S37: AT | T37: เบนซิน | U37: สุวินทวงศ์
C38: หมายเหตุ: ออกใบแทนคู่มือทะเบียนใหม่ กรณีรายการต่อเต็ม กรณีเอกสารหมดอายุหรือสูญหาย ขอเอกสารใหม่มีค่าใช้จ่าย 500 บาท
B39: 1019 | C39: Isuzu | D39: D-Max | E39: Smart Cab | F39: Hi-Lander Z | G39: E | H39: 130000 | I39: 10000 | J39: 152000 | K39: 2012 | L39: 3ฒน-9631 | M39: กรุงเทพมหานคร | N39: 2013 | O39: 206814 | P39: RWD | Q39: 2.5 | R39: เทา | S39: MT | T39: ดีเซล | U39: สุวินทวงศ์
C40: หมายเหตุ: เบาะโดยสารคู่หน้ามีการดัดแปลงมา ขายตามสภาพ ผู้ซื้อดำเนินการเอง กรณีเอกสารหมดอายุหรือสูญหาย ขอเอกสารใหม่มีค่าใช้จ่าย 500 บาท
...

Sheet 09012025
C1: 45666 | D1: 161 | E1: =COUNTA(B:B)-1 -> 161
A2: รูปภาพ | B2: ลำดับที่ | C2: ยี่ห้อ | D2: รุ่น | E2: ประเภทรถกระบะ | F2: รุ่นย่อย | G2: เกรด | H2: ราคาเริ่มต้น (ไม่รวมvat) | I2: ค่าธรรมเนียม (ไม่รวมvat) | J2: ราคาสูงสุด | K2: ปีที่ผลิต | L2: ป้ายทะเบียนรถ | M2: จังหวัด | N2: ปีที่จดทะเบียน | O2: เลขไมล์ (กม.) | P2: ระบบขับเคลื่อน | Q2: ความจุ (CC) | R2: สี | S2: ระบบเกียร์ | T2: เชื้อเพลิง | U2: สถานที่จอดรถ | V2: ประเภทรถประมูล
B3: 1001 | C3: Toyota | D3: Yaris Ativ | F3: Sport | G3: A+ | H3: 316000 | I3: 21600 | J3: 368000 | K3: 2023 | L3: กท-4451 | M3: ปัตตานี | N3: 2024 | O3: 8642 | P3: FWD | Q3: 1.2 | R3: ขาว | S3: AT | T3: เบนซิน | U3: สุวินทวงศ์ | V3: ถูกยึดคืน
C4: หมายเหตุ: ค่าเช็คต้น 100 บาท ภาษีหมดอายุ 16-02-25 ผู้ซื้อต้องดำเนินการต่อภาษีเอง กรณีไม่มีป้ายภาษี ผู้ซื้อต้องรับผิดชอบคัดป้ายใหม่เอง กรณีรถติดอายัดจราจร หรือ มีค่าใช้จ่ายคงค้างจากการใช้ทางด่วน/M-flow ผู้ซื้อเป็นผู้รับผิดชอบค่าใช้จ่ายทุกกรณี
B5: 1002 | C5: Toyota | D5: Fortuner | F5: V | G5: B | H5: 582000 | I5: 19600 | J5: 632000 | K5: 2019 | L5: ขง-5361 | M5: เชียงราย | N5: 2022 | O5: 137304 | P5: RWD | Q5: 2.4 | R5: เทา ดำ | S5: AT | T5: ดีเซล | U5: สุวินทวงศ์ | V5: ถูกยึดคืน
C6: หมายเหตุ: เปลี่ยนสีมา ลงเล่มแล้ว มีค่าปรับ M-FLOW 660 บาท ค่าเช็คต้น 100 บาท ภาษีหมดอายุ 08-09-25 ผู้ซื้อต้องดำเนินการต่อภาษีเอง กรณีไม่มีป้ายภาษี ผู้ซื้อต้องรับผิดชอบคัดป้ายใหม่เอง กรณีรถติดอายัดจราจร หรือ มีค่าใช้จ่ายคงค้างจากการใช้ทางด่วน/M-flow ผู้ซื้อเป็นผู้รับผิดชอบค่าใช้จ่ายทุกกรณี
B7: 1003 | C7: Toyota | D7: Hilux Champ | E7: Single Cab | F7: Attractive Package | G7: A+ | H7: 335000 | I7: 18400 | J7: 417000 | K7: 2024 | L7: ผบ-8822 | M7: ระยอง | N7: 2024 | O7: 14748 | P7: RWD | Q7: 2.4 | R7: เทา | S7: AT | T7: ดีเซล | U7: สุวินทวงศ์ | V7: ถูกยึดคืน
C8: หมายเหตุ: แจ้งหยุดใช้รถ เพื่อแขวนป้ายประมูลให้กับเจ้าของเดิม ขายไม่รวมป้าย ไม่มีแผ่นป้ายทะเบียน ผู้ซื้อต้องดำเนินการจดป้ายใหม่เอง ค่าเช็คต้น 100 บาท ภาษีหมดอายุ 20-06-25 ผู้ซื้อต้องดำเนินการต่อภาษีเอง กรณีไม่มีป้ายภาษี ผู้ซื้อต้องรับผิดชอบคัดป้ายใหม่เอง กรณีรถติดอายัดจราจร หรือ มีค่าใช้จ่ายคงค้างจากการใช้ทางด่วน/M-flow ผู้ซื้อเป็นผู้รับผิดชอบค่าใช้จ่ายทุกกรณี
B9: 1004 | C9: Toyota | D9: Yaris | F9: Premium | G9: F | H9: 260000 | I9: 19600 | J9: 305000 | K9: 2023 | L9: 4ขฉ-1513 | M9: กรุงเทพมหานคร | N9: 2023 | O9: 33307 | P9: FWD | Q9: 1.2 | R9: เทา | S9: AT | T9: เบนซิน | U9: สุวินทวงศ์ | V9: ถูกยึดคืน
C10: หมายเหตุ: ค่าเช็คต้น 100 บาท ภาษีหมดอายุ 26-04-24 ผู้ซื้อต้องดำเนินการต่อภาษีเอง กรณีไม่มีป้ายภาษี ผู้ซื้อต้องรับผิดชอบคัดป้ายใหม่เอง กรณีรถติดอายัดจราจร หรือ มีค่าใช้จ่ายคงค้างจากการใช้ทางด่วน/M-flow ผู้ซื้อเป็นผู้รับผิดชอบค่าใช้จ่ายทุกกรณี
B11: 1005 | C11: Toyota | D11: Hilux Revo | E11: Double Cab | F11: Prerunner Entry | G11: A | H11: 430000 | I11: 15600 | J11: 538000 | K11: 2023 | L11: 5ขค-7574 | M11: กรุงเทพมหานคร | N11: 2024 | O11: 7718 | P11: RWD | Q11: 2.4 | R11: เทา | S11: MT | T11: ดีเซล | U11: สุวินทวงศ์ | V11: ถูกยึดคืน
C12: หมายเหตุ: ค่าเช็คต้น 100 บาท ภาษีหมดอายุ 15-01-25 ผู้ซื้อต้องดำเนินการต่อภาษีเอง กรณีไม่มีป้ายภาษี ผู้ซื้อต้องรับผิดชอบคัดป้ายใหม่เอง กรณีรถติดอายัดจราจร หรือ มีค่าใช้จ่ายคงค้างจากการใช้ทางด่วน/M-flow ผู้ซื้อเป็นผู้รับผิดชอบค่าใช้จ่ายทุกกรณี
B13: 1006 | C13: Toyota | D13: Veloz | F13: Premium | G13: A | H13: 440000 | I13: 15600 | J13: 540000 | K13: 2022 | L13: กฉ-7829 | M13: นครนายก | N13: 2023 | O13: 62973 | P13: FWD | Q13: 1.5 | R13: เทา | S13: AT | T13: เบนซิน | U13: สุวินทวงศ์ | V13: ถูกยึดคืน
C14: หมายเหตุ: ค่าเช็คต้น 100 บาท ภาษีหมดอายุ 20-01-25 ผู้ซื้อต้องดำเนินการต่อภาษีเอง กรณีไม่มีป้ายภาษี ผู้ซื้อต้องรับผิดชอบคัดป้ายใหม่เอง กรณีรถติดอายัดจราจร หรือ มีค่าใช้จ่ายคงค้างจากการใช้ทางด่วน/M-flow ผู้ซื้อเป็นผู้รับผิดชอบค่าใช้จ่ายทุกกรณี
B15: 1007 | C15: Toyota | D15: Hilux Revo | E15: Double Cab | F15: Z Edition Mid | G15: C | H15: 320000 | I15: 19600 | J15: 391000 | K15: 2020 | L15: กน-5226 | M15: กระบี่ | N15: 2020 | O15: 41494 | P15: RWD | Q15: 2.4 | R15: เทา | S15: AT | T15: ดีเซล | U15: สุวินทวงศ์ | V15: ถูกยึดคืน
C16: หมายเหตุ: ค่าเช็คต้น 100 บาท ภาษีหมดอายุ 31-08-24 ผู้ซื้อต้องดำเนินการต่อภาษีเอง กรณีไม่มีป้ายภาษี ผู้ซื้อต้องรับผิดชอบคัดป้ายใหม่เอง กรณีรถติดอายัดจราจร หรือ มีค่าใช้จ่ายคงค้างจากการใช้ทางด่วน/M-flow ผู้ซื้อเป็นผู้รับผิดชอบค่าใช้จ่ายทุกกรณี
B17: 1008 | C17: Toyota | D17: Hilux Revo | E17: Smart Cab | F17: Z Edition Entry | G17: B | H17: 210000 | I17: 19600 | J17: 260000 | K17: 2020 | L17: บษ-4134 | M17: พระนครศรีอยุธยา | N17: 2020 | O17: 64827 | P17: RWD | Q17: 2.4 | R17: ขาว | S17: MT | T17: ดีเซล | U17: สุวินทวงศ์ | V17: ถูกยึดคืน
C18: หมายเหตุ: มีค่าปรับ M-FLOW 330 บาท ค่าเช็คต้น 100 บาท ภาษีหมดอายุ 02-12-23 ผู้ซื้อต้องดำเนินการต่อภาษีเอง กรณีไม่มีป้ายภาษี ผู้ซื้อต้องรับผิดชอบคัดป้ายใหม่เอง กรณีรถติดอายัดจราจร หรือ มีค่าใช้จ่ายคงค้างจากการใช้ทางด่วน/M-flow ผู้ซื้อเป็นผู้รับผิดชอบค่าใช้จ่ายทุกกรณี
B19: 1009 | C19: Mazda | D19: 3 | F19: SP Sports | G19: A+ | H19: 612000 | I19: 19600 | J19: 698000 | K19: 2022 | L19: 5ขพ-9820 | M19: กรุงเทพมหานคร | N19: 2024 | O19: 19887 | P19: FWD | Q19: 2 | R19: น้ำตาล | S19: AT | T19: เบนซิน | U19: สุวินทวงศ์ | V19: ถูกยึดคืน
C20: หมายเหตุ: ค่าเช็คต้น 100 บาท ภาษีหมดอายุ 15-08-25 ผู้ซื้อต้องดำเนินการต่อภาษีเอง กรณีไม่มีป้ายภาษี ผู้ซื้อต้องรับผิดชอบคัดป้ายใหม่เอง กรณีรถติดอายัดจราจร หรือ มีค่าใช้จ่ายคงค้างจากการใช้ทางด่วน/M-flow ผู้ซื้อเป็นผู้รับผิดชอบค่าใช้จ่ายทุกกรณี
B21: 1010 | C21: Toyota | D21: Hilux Revo | E21: Single Cab | F21: Entry | G21: D | H21: 270000 | I21: 19600 | J21: 356000 | K21: 2022 | L21: บว-281 | M21: ชุมพร | N21: 2023 | O21: 111559 | P21: RWD | Q21: 2.8 | R21: เทา | S21: MT | T21: ดีเซล | U21: สุวินทวงศ์ | V21: ถูกยึดคืน
C22: หมายเหตุ: ค่าเช็คต้น 100 บาท ภาษีหมดอายุ 26-01-24 ผู้ซื้อต้องดำเนินการต่อภาษีเอง กรณีไม่มีป้ายภาษี ผู้ซื้อต้องรับผิดชอบคัดป้ายใหม่เอง กรณีรถติดอายัดจราจร หรือ มีค่าใช้จ่ายคงค้างจากการใช้ทางด่วน/M-flow ผู้ซื้อเป็นผู้รับผิดชอบค่าใช้จ่ายทุกกรณี
B23: 1011 | C23: Toyota | D23: Hilux Revo | E23: Smart Cab | F23: Prerunner Entry | G23: D | H23: 320000 | I23: 19600 | J23: 356000 | K23: 2022 | L23: บห-3304 | M23: พระนครศรีอยุธยา | N23: 2022 | O23: 55880 | P23: RWD | Q23: 2.4 | R23: เทา | S23: MT | T23: ดีเซล | U23: สุวินทวงศ์ | V23: ถูกยึดคืน
C24: หมายเหตุ: มีค่าปรับ M-FLOW 660 บาท ค่าเช็คต้น 100 บาท ภาษีหมดอายุ 23-05-23 ผู้ซื้อต้องดำเนินการต่อภาษีเอง กรณีไม่มีป้ายภาษี ผู้ซื้อต้องรับผิดชอบคัดป้ายใหม่เอง กรณีรถติดอายัดจราจร หรือ มีค่าใช้จ่ายคงค้างจากการใช้ทางด่วน/M-flow ผู้ซื้อเป็นผู้รับผิดชอบค่าใช้จ่ายทุกกรณี
B25: 1012 | C25: Toyota | D25: C-HR | F25: HV Hi | G25: C | H25: 255000 | I25: 19600 | J25: 387000 | K25: 2018 | L25: 8กฉ-1731 | M25: กรุงเทพมหานคร | N25: 2019 | O25: 88956 | P25: FWD | Q25: 1.8 | R25: เทา | S25: AT | T25: ไฮบริด | U25: สุวินทวงศ์ | V25: ถูกยึดคืน
C26: หมายเหตุ: ค่าเช็คต้น 100 บาท ภาษีหมดอายุ 03-01-25 ผู้ซื้อต้องดำเนินการต่อภาษีเอง กรณีไม่มีป้ายภาษี ผู้ซื้อต้องรับผิดชอบคัดป้ายใหม่เอง กรณีรถติดอายัดจราจร หรือ มีค่าใช้จ่ายคงค้างจากการใช้ทางด่วน/M-flow ผู้ซื้อเป็นผู้รับผิดชอบค่าใช้จ่ายทุกกรณี
B27: 1013 | C27: Toyota | D27: Hilux Revo | E27: Single Cab | F27: Entry | G27: D | H27: 362000 | I27: 20900 | J27: 420000 | K27: 2023 | L27: ผพ-4262 | M27: อุดรธานี | N27: 2023 | O27: 41326 | P27: 4WD | Q27: 2.8 | R27: เทา | S27: MT | T27: ดีเซล | U27: สุวินทวงศ์ | V27: ถูกยึดคืน
C28: หมายเหตุ: รถจดทะเบียนลักษณะกระบะบรรทุก(แบบยกได้) ค่าเช็คต้น 100 บาท ภาษีหมดอายุ 10-04-24 ผู้ซื้อต้องดำเนินการต่อภาษีเอง กรณีไม่มีป้ายภาษี ผู้ซื้อต้องรับผิดชอบคัดป้ายใหม่เอง กรณีรถติดอายัดจราจร หรือ มีค่าใช้จ่ายคงค้างจากการใช้ทางด่วน/M-flow ผู้ซื้อเป็นผู้รับผิดชอบค่าใช้จ่ายทุกกรณี
B29: 1014 | C29: Toyota | D29: Hilux Vigo | E29: Double Cab | F29: Prerunner E | G29: B | H29: 160000 | I29: 18400 | J29: 280000 | K29: 2013 | L29: ขท-5928 | M29: ชลบุรี | N29: 2013 | O29: 122017 | P29: RWD | Q29: 2.5 | R29: ดำ | S29: AT | T29: ดีเซล | U29: สุวินทวงศ์ | V29: ถูกยึดคืน
C30: หมายเหตุ: เลขเครื่องเป็นสนิม ขายตามสภาพ มีค่าปรับ M-FLOW 1,980 บาท ค่าเช็คต้น 100 บาท ภาษีหมดอายุ 20-05-24 ผู้ซื้อต้องดำเนินการต่อภาษีเอง กรณีไม่มีป้ายภาษี ผู้ซื้อต้องรับผิดชอบคัดป้ายใหม่เอง กรณีรถติดอายัดจราจร หรือ มีค่าใช้จ่ายคงค้างจากการใช้ทางด่วน/M-flow ผู้ซื้อเป็นผู้รับผิดชอบค่าใช้จ่ายทุกกรณี
B31: 1015 | C31: Toyota | D31: Yaris | F31: Sport | G31: D | H31: 260000 | I31: 18900 | J31: 330000 | K31: 2023 | L31: กย-9674 | M31: กาญจนบุรี | N31: 2023 | O31: 10172 | P31: FWD | Q31: 1.2 | R31: เทา | S31: AT | T31: เบนซิน | U31: สุวินทวงศ์ | V31: ถูกยึดคืน
C32: หมายเหตุ: ค่าเช็คต้น 100 บาท ภาษีหมดอายุ 02-06-24 ผู้ซื้อต้องดำเนินการต่อภาษีเอง กรณีไม่มีป้ายภาษี ผู้ซื้อต้องรับผิดชอบคัดป้ายใหม่เอง กรณีรถติดอายัดจราจร หรือ มีค่าใช้จ่ายคงค้างจากการใช้ทางด่วน/M-flow ผู้ซื้อเป็นผู้รับผิดชอบค่าใช้จ่ายทุกกรณี
B33: 1016 | C33: Toyota | D33: Camry | F33: HEV Premium | G33: B | H33: 701000 | I33: 32196 | J33: 866000 | K33: 2021 | L33: 1ขล-1552 | M33: กรุงเทพมหานคร | N33: 2021 | O33: 91800 | P33: FWD | Q33: 2.5 | R33: ดำ | S33: AT | T33: ไฮบริด | U33: สุวินทวงศ์ | V33: Op-เช่า
C34: หมายเหตุ: บังคับโอนกรรมสิทธิ์ผ่านผู้ขาย ค่าโอนกรรมสิทธิ์ 3000 บาท ค่าภาษีเรียกเก็บคืนผู้ขาย 9,696 บาท
B35: 1017 | C35: Honda | D35: Accord | F35: TURBO EL | G35: B | H35: 571000 | I35: 21294 | J35: 721000 | K35: 2021 | L35: 2ขฉ-6090 | M35: กรุงเทพมหานคร | N35: 2021 | O35: 88927 | P35: FWD | Q35: 1.5 | R35: ดำ | S35: AT | T35: เบนซิน | U35: สุวินทวงศ์ | V35: Op-เช่า
C36: หมายเหตุ: บังคับโอนกรรมสิทธิ์ผ่านผู้ขาย ค่าโอนกรรมสิทธิ์ 3000 บาท ค่าภาษีเรียกเก็บคืนผู้ขาย 3,294 บาท
B37: 1018 | C37: Toyota | D37: Fortuner | F37: V | G37: C | H37: 760000 | I37: 18000 | J37: 736000 | K37: 2019 | L37: 9กฐ-4197 | M37: กรุงเทพมหานคร | N37: 2019 | O37: 184612 | P37: 4WD | Q37: 2.4 | R37: ดำ | S37: AT | T37: ดีเซล | U37: สุวินทวงศ์
C38: หมายเหตุ: บังคับโอน 2 ต่อ ค่าโอนกรรมสิทธิ์ 3000 บาท กรณีติดอายัดจราจรผู้ซื้อเป็นผู้รับผิดชอบทุกกรณี
B39: 1019 | C39: Toyota | D39: Hilux Revo | E39: Double Cab | F39: Z Edition Entry | G39: A+ | H39: 460000 | I39: 16600 | J39: 0 | K39: 2023 | L39: 5ขฆ-5729 | M39: กรุงเทพมหานคร | N39: 2024 | O39: 6126 | P39: RWD | Q39: 2.4 | R39: เทา | S39: AT | T39: ดีเซล | U39: สุวินทวงศ์ | V39: ถูกยึดคืน
C40: หมายเหตุ: ค่าเช็คต้น 100 บาท ภาษีหมดอายุ 19-01-25 ผู้ซื้อต้องดำเนินการต่อภาษีเอง กรณีไม่มีป้ายภาษี ผู้ซื้อต้องรับผิดชอบคัดป้ายใหม่เอง กรณีรถติดอายัดจราจร หรือ มีค่าใช้จ่ายคงค้างจากการใช้ทางด่วน/M-flow ผู้ซื้อเป็นผู้รับผิดชอบค่าใช้จ่ายทุกกรณี
...

Sheet 13012025
C1: 45670 | D1: 95 | E1: =COUNTA(B:B)-1 -> 95
A2: รูปภาพ | B2: ลำดับที่ | C2: ยี่ห้อ | D2: รุ่น | E2: ประเภทรถกระบะ | F2: รุ่นย่อย | G2: เกรด | H2: ราคาเริ่มต้น (ไม่รวมvat) | I2: ค่าธรรมเนียม (ไม่รวมvat) | J2: ราคาสูงสุด | K2: ปีที่ผลิต | L2: ป้ายทะเบียนรถ | M2: จังหวัด | N2: ปีที่จดทะเบียน | O2: เลขไมล์ (กม.) | P2: ระบบขับเคลื่อน | Q2: ความจุ (CC) | R2: สี | S2: ระบบเกียร์ | T2: เชื้อเพลิง | U2: สถานที่จอดรถ | V2: ประเภทรถประมูล
B3: 1001 | C3: Toyota | D3: Corolla Cross | F3: Hybrid Premium Safety | G3: A+ | H3: 700000 | I3: 17400 | J3: 762000 | K3: 2022 | L3: 3ขฎ-7605 | M3: กรุงเทพมหานคร | N3: 2022 | O3: 27261 | P3: FWD | Q3: 1.8 | R3: ดำ | S3: AT | T3: ไฮบริด | U3: สุวินทวงศ์ | V3: ถูกยึดคืน
C4: หมายเหตุ: ค่าเช็คต้น 100 บาท ภาษีหมดอายุ 07-09-25 ผู้ซื้อต้องดำเนินการต่อภาษีเอง กรณีไม่มีป้ายภาษี ผู้ซื้อต้องรับผิดชอบคัดป้ายใหม่เอง กรณีรถติดอายัดจราจร หรือ มีค่าใช้จ่ายคงค้างจากการใช้ทางด่วน/M-flow ผู้ซื้อเป็นผู้รับผิดชอบค่าใช้จ่ายทุกกรณี
B5: 1002 | C5: Toyota | D5: Yaris | F5: Sport Premium | G5: A | H5: 290000 | I5: 15600 | J5: 362000 | K5: 2021 | L5: 2ขต-3947 | M5: กรุงเทพมหานคร | N5: 2021 | O5: 21261 | P5: FWD | Q5: 1.2 | R5: ขาว ดำ | S5: AT | T5: เบนซิน | U5: สุวินทวงศ์ | V5: ถูกยึดคืน
C6: หมายเหตุ: ค่าเช็คต้น 100 บาท ภาษีหมดอายุ 18-10-25 ผู้ซื้อต้องดำเนินการต่อภาษีเอง กรณีไม่มีป้ายภาษี ผู้ซื้อต้องรับผิดชอบคัดป้ายใหม่เอง กรณีรถติดอายัดจราจร หรือ มีค่าใช้จ่ายคงค้างจากการใช้ทางด่วน/M-flow ผู้ซื้อเป็นผู้รับผิดชอบค่าใช้จ่ายทุกกรณี
B7: 1003 | C7: Toyota | D7: Hilux Revo | E7: Smart Cab | F7: Z Edition Entry | G7: A+ | H7: 320000 | I7: 17400 | J7: 406000 | K7: 2023 | L7: ผพ-474 | M7: อุบลราชธานี | N7: 2024 | O7: 21114 | P7: RWD | Q7: 2.4 | R7: ขาว | S7: AT | T7: ดีเซล | U7: สุวินทวงศ์ | V7: ถูกยึดคืน
C8: หมายเหตุ: ค่าเช็คต้น 100 บาท ภาษีหมดอายุ 03-05-25 ผู้ซื้อต้องดำเนินการต่อภาษีเอง กรณีไม่มีป้ายภาษี ผู้ซื้อต้องรับผิดชอบคัดป้ายใหม่เอง กรณีรถติดอายัดจราจร หรือ มีค่าใช้จ่ายคงค้างจากการใช้ทางด่วน/M-flow ผู้ซื้อเป็นผู้รับผิดชอบค่าใช้จ่ายทุกกรณี
B9: 1004 | C9: Toyota | D9: Hilux Revo | E9: Single Cab | F9: Entry | G9: C | H9: 255000 | I9: 21600 | J9: 275000 | K9: 2022 | L9: ผผ-8608 | M9: สงขลา | N9: 2022 | O9: 35996 | P9: RWD | Q9: 2.8 | R9: เทา | S9: MT | T9: ดีเซล | U9: สุวินทวงศ์ | V9: ถูกยึดคืน
C10: หมายเหตุ: ค่าเช็คต้น 100 บาท ภาษีหมดอายุ 27-07-23 ผู้ซื้อต้องดำเนินการต่อภาษีเอง กรณีไม่มีป้ายภาษี ผู้ซื้อต้องรับผิดชอบคัดป้ายใหม่เอง กรณีรถติดอายัดจราจร หรือ มีค่าใช้จ่ายคงค้างจากการใช้ทางด่วน/M-flow ผู้ซื้อเป็นผู้รับผิดชอบค่าใช้จ่ายทุกกรณี
B11: 1005 | C11: Toyota | D11: Hilux Revo | E11: Double Cab | F11: Prerunner E Plus | G11: D | H11: 340000 | I11: 15600 | J11: 436000 | K11: 2018 | L11: 7กฮ-2298 | M11: กรุงเทพมหานคร | N11: 2018 | O11: 91388 | P11: RWD | Q11: 2.4 | R11: ดำ | S11: AT | T11: ดีเซล | U11: สุวินทวงศ์ | V11: ถูกยึดคืน
C12: หมายเหตุ: มีค่าปรับ M-FLOW 1,320 บาท ค่าเช็คต้น 100 บาท ภาษีหมดอายุ 02-11-22 ผู้ซื้อต้องดำเนินการต่อภาษีเอง กรณีไม่มีป้ายภาษี ผู้ซื้อต้องรับผิดชอบคัดป้ายใหม่เอง กรณีรถติดอายัดจราจร หรือ มีค่าใช้จ่ายคงค้างจากการใช้ทางด่วน/M-flow ผู้ซื้อเป็นผู้รับผิดชอบค่าใช้จ่ายทุกกรณี
B13: 1006 | C13: Toyota | D13: Yaris Ativ | F13: Sport | G13: C | H13: 300000 | I13: 19600 | J13: 352000 | K13: 2023 | L13: ขจ-7694 | M13: อุบลราชธานี | N13: 2023 | O13: 20828 | P13: FWD | Q13: 1.2 | R13: ขาว | S13: AT | T13: เบนซิน | U13: สุวินทวงศ์ | V13: ถูกยึดคืน
C14: หมายเหตุ: ค่าเช็คต้น 100 บาท ภาษีหมดอายุ 29-09-24 ผู้ซื้อต้องดำเนินการต่อภาษีเอง กรณีไม่มีป้ายภาษี ผู้ซื้อต้องรับผิดชอบคัดป้ายใหม่เอง กรณีรถติดอายัดจราจร หรือ มีค่าใช้จ่ายคงค้างจากการใช้ทางด่วน/M-flow ผู้ซื้อเป็นผู้รับผิดชอบค่าใช้จ่ายทุกกรณี
B15: 1007 | C15: Toyota | D15: Hilux Revo | E15: Double Cab | F15: Z Edition Entry | G15: B | H15: 320000 | I15: 18400 | J15: 374000 | K15: 2023 | L15: ขร-6957 | M15: ระยอง | N15: 2023 | O15: 41703 | P15: RWD | Q15: 2.4 | R15: เทา | S15: MT | T15: ดีเซล | U15: สุวินทวงศ์ | V15: ถูกยึดคืน
C16: หมายเหตุ: ค่าเช็คต้น 100 บาท ภาษีหมดอายุ 01-11-24 ผู้ซื้อต้องดำเนินการต่อภาษีเอง กรณีไม่มีป้ายภาษี ผู้ซื้อต้องรับผิดชอบคัดป้ายใหม่เอง กรณีรถติดอายัดจราจร หรือ มีค่าใช้จ่ายคงค้างจากการใช้ทางด่วน/M-flow ผู้ซื้อเป็นผู้รับผิดชอบค่าใช้จ่ายทุกกรณี
B17: 1008 | C17: Toyota | D17: Hilux Revo | E17: Smart Cab | F17: Z Edition Entry | G17: C | H17: 270000 | I17: 19600 | J17: 276000 | K17: 2022 | L17: บว-8130 | M17: กาฬสินธุ์ | N17: 2022 | O17: 119460 | P17: RWD | Q17: 2.4 | R17: ขาว | S17: MT | T17: ดีเซล | U17: สุวินทวงศ์ | V17: ถูกยึดคืน
C18: หมายเหตุ: ค่าเช็คต้น 100 บาท ภาษีหมดอายุ 21-04-25 ผู้ซื้อต้องดำเนินการต่อภาษีเอง กรณีไม่มีป้ายภาษี ผู้ซื้อต้องรับผิดชอบคัดป้ายใหม่เอง กรณีรถติดอายัดจราจร หรือ มีค่าใช้จ่ายคงค้างจากการใช้ทางด่วน/M-flow ผู้ซื้อเป็นผู้รับผิดชอบค่าใช้จ่ายทุกกรณี
B19: 1009 | C19: Toyota | D19: Hilux Revo | E19: Smart Cab | F19: Z Edition Entry | G19: C | H19: 360000 | I19: 16900 | J19: 360000 | K19: 2022 | L19: 3ฒภ-9353 | M19: กรุงเทพมหานคร | N19: 2022 | O19: 43765 | P19: RWD | Q19: 2.4 | R19: เทา | S19: AT | T19: ดีเซล | U19: สุวินทวงศ์
C20: หมายเหตุ: หากเอกสารหมดอายุหรือสูญหาย ขอเอกสารใหม่มีค่าใช้จ่าย 2,000 บาท
B21: 1010 | C21: Toyota | D21: Hilux Revo | E21: Single Cab | F21: J | G21: E | H21: 144000 | I21: 14500 | J21: 144000 | K21: 2018 | L21: 2ฒพ-2005 | M21: กรุงเทพมหานคร | N21: 2019 | O21: 289598 | P21: RWD | Q21: 2.4 | R21: ขาว แดง เขียว | S21: MT | T21: ดีเซล | U21: สุวินทวงศ์
C22: หมายเหตุ: ผู้ซื้อต้องทำการโอนกรรมสิทธิ์ 2 ต่อ เล่มทะเบียนชุดโอนจัดส่งภายใน 30 วัน หลังการประมูล หากเอกสารหมดอายุ ขอเอกสารใหม่ มีค่าใช้จ่าย 1,500 บาท กรณีภาษีหมดอายุ/ไม่มีป้ายภาษี ผู้ซื้อต้องต่อภาษีและรับผิดชอบคัดป้ายใหม่เอง
B23: 1011 | C23: Isuzu | D23: D-Max | E23: Double Cab | F23: Hi-Lander Z | G23: E | H23: 460000 | I23: 10000 | J23: 540000 | K23: 2022 | L23: 3ขก-1194 | M23: กรุงเทพมหานคร | N23: 2022 | O23: 99271 | P23: RWD | Q23: 1.9 | R23: เทา | S23: AT | T23: ดีเซล | U23: สุวินทวงศ์
C24: หมายเหตุ: (KA) กรณีเอกสารหมดอายุหรือสูญหาย ขอเอกสารใหม่มีค่าใช้จ่าย 500 บาท
B25: 1012 | C25: Mitsubishi | D25: Triton | E25: Smart Cab | F25: GLX | G25: C | H25: 180000 | I25: 10000 | J25: 206000 | K25: 2019 | L25: บว-9831 | M25: พระนครศรีอยุธยา | N25: 2020 | O25: 127812 | P25: RWD | Q25: 2.5 | R25: เทา | S25: MT | T25: ดีเซล | U25: สุวินทวงศ์
C26: หมายเหตุ: มีค่าปรับ M-flow 330 บาท กรณีเอกสารหมดอายุหรือสูญหาย ขอเอกสารใหม่มีค่าใช้จ่าย 500 บาท
B27: 1013 | C27: Toyota | D27: Yaris Ativ | F27: Sport | G27: C | H27: 220000 | I27: 10000 | J27: 282000 | K27: 2021 | L27: 2ขท-7813 | M27: กรุงเทพมหานคร | N27: 2022 | O27: 52994 | P27: FWD | Q27: 1.2 | R27: ขาว | S27: AT | T27: เบนซิน | U27: สุวินทวงศ์
C28: หมายเหตุ: ไม่มีแผ่นป้ายทะเบียนหลัง ผู้ซื้อดำเนินการคัดป้ายใหม่เอง รถติดอายัดจราจร มีใบสั่ง 1 ใบ ปรับ 500 บาท กรณีเอกสารหมดอายุหรือสูญหาย ขอเอกสารใหม่มีค่าใช้จ่าย 500 บาท
B29: 1014 | C29: Isuzu | D29: D-Max | E29: Double Cab | F29: Hi-Lander Z-Prestige | G29: C | H29: 220000 | I29: 10000 | J29: 282000 | K29: 2015 | L29: 5กณ-6097 | M29: กรุงเทพมหานคร | N29: 2016 | O29: 149793 | P29: RWD | Q29: 3 | R29: ขาว | S29: MT | T29: ดีเซล | U29: สุวินทวงศ์
C30: หมายเหตุ: กรณีเอกสารหมดอายุหรือสูญหาย ขอเอกสารใหม่มีค่าใช้จ่าย 500 บาท
B31: 1015 | C31: Toyota | D31: Fortuner | F31: Legender | G31: A | H31: 950000 | I31: 10000 | J31: 1072000 | K31: 2021 | L31: 2ขล-7769 | M31: กรุงเทพมหานคร | N31: 2022 | O31: 77282 | P31: 4WD | Q31: 2.4 | R31: ขาว ดำ | S31: AT | T31: ดีเซล | U31: สุวินทวงศ์
C32: หมายเหตุ: (KA) กรณีเอกสารหมดอายุหรือสูญหาย ขอเอกสารใหม่มีค่าใช้จ่าย 500 บาท
B33: 1016 | C33: Isuzu | D33: D-Max | E33: Smart Cab | F33: Hi-Lander L | G33: A | H33: 250000 | I33: 10000 | J33: 304000 | K33: 2019 | L33: 3ฒอ-6719 | M33: กรุงเทพมหานคร | N33: 2019 | O33: 74045 | P33: RWD | Q33: 1.9 | R33: ขาว | S33: MT | T33: ดีเซล | U33: สุวินทวงศ์
C34: หมายเหตุ: (KA) กรณีเอกสารหมดอายุหรือสูญหาย ขอเอกสารใหม่มีค่าใช้จ่าย 500 บาท
B35: 1017 | C35: Honda | D35: Civic | F35: S i-VTEC | G35: F | H35: 70000 | I35: 10000 | J35: 92000 | K35: 2009 | L35: 2ขต-7197 | M35: กรุงเทพมหานคร | N35: 2010 | O35: 150068 | P35: FWD | Q35: 1.8 | R35: เทา | S35: AT | T35: เบนซิน | U35: สุวินทวงศ์
C36: หมายเหตุ: ออกใบแทนคู่มือทะเบียนใหม่ กรณีรายการต่อเต็ม กรณีเอกสารหมดอายุหรือสูญหาย ขอเอกสารใหม่มีค่าใช้จ่าย 500 บาท
B37: 1018 | C37: Nissan | D37: March | F37: S | G37: C | H37: 80000 | I37: 10000 | J37: 86000 | K37: 2019 | L37: กธ-3201 | M37: สระแก้ว | N37: 2019 | O37: 68732 | P37: FWD | Q37: 1.2 | R37: ดำ | S37: MT | T37: เบนซิน | U37: สุวินทวงศ์
C38: หมายเหตุ: กรณีเอกสารหมดอายุหรือสูญหาย ขอเอกสารใหม่มีค่าใช้จ่าย 500 บาท
B39: 1019 | C39: Isuzu | D39: D-Max | E39: Double Cab | F39: Hi-Lander L DA | G39: B | H39: 420000 | I39: 10000 | J39: 522000 | K39: 2022 | L39: กธ-4506 | M39: สระแก้ว | N39: 2022 | O39: 21094 | P39: RWD | Q39: 1.9 | R39: เทา | S39: MT | T39: ดีเซล | U39: สุวินทวงศ์
C40: หมายเหตุ: (KA) รถติดอายัดจราจร มีใบสั่ง 1 ใบ ปรับ 500 บาท กรณีเอกสารหมดอายุหรือสูญหาย ขอเอกสารใหม่มีค่าใช้จ่าย 500 บาท
...

Sheet 16012025
C1: 45673 | D1: 102 | E1: =COUNTA(B:B)-1 -> 102
A2: รูปภาพ | B2: ลำดับที่ | C2: ยี่ห้อ | D2: รุ่น | E2: ประเภทรถกระบะ | F2: รุ่นย่อย | G2: เกรด | H2: ราคาเริ่มต้น (ไม่รวมvat) | I2: ค่าธรรมเนียม (ไม่รวมvat) | J2: ราคาสูงสุด | K2: ปีที่ผลิต | L2: ป้ายทะเบียนรถ | M2: จังหวัด | N2: ปีที่จดทะเบียน | O2: เลขไมล์ (กม.) | P2: ระบบขับเคลื่อน | Q2: ความจุ (CC) | R2: สี | S2: ระบบเกียร์ | T2: เชื้อเพลิง | U2: สถานที่จอดรถ | V2: ประเภทรถประมูล
B3: 1001 | C3: Toyota | D3: Hilux Revo | E3: Double Cab | F3: Prerunner Rocco | G3: A | H3: 550000 | I3: 19600 | J3: 756000 | K3: 2023 | L3: ขฉ-835 | M3: อุบลราชธานี | N3: 2024 | O3: 25344 | P3: RWD | Q3: 2.4 | R3: ขาว | S3: AT | T3: ดีเซล | U3: สุวินทวงศ์ | V3: ถูกยึดคืน
C4: หมายเหตุ: ค่าเช็คต้น 100 บาท ภาษีหมดอายุ 03-01-25 ผู้ซื้อต้องดำเนินการต่อภาษีเอง กรณีไม่มีป้ายภาษี ผู้ซื้อต้องรับผิดชอบคัดป้ายใหม่เอง กรณีรถติดอายัดจราจร หรือ มีค่าใช้จ่ายคงค้างจากการใช้ทางด่วน/M-flow ผู้ซื้อเป็นผู้รับผิดชอบค่าใช้จ่ายทุกกรณี
B5: 1002 | C5: Toyota | D5: Corolla Cross | F5: HEV Premium | G5: A+ | H5: 650000 | I5: 17400 | J5: 694000 | K5: 2023 | L5: 4ขธ-9265 | M5: กรุงเทพมหานคร | N5: 2023 | O5: 58309 | P5: FWD | Q5: 1.8 | R5: เทา | S5: AT | T5: ไฮบริด | U5: สุวินทวงศ์ | V5: ถูกยึดคืน
C6: หมายเหตุ: มีค่าปรับ M-FLOW 600 บาท ค่าเช็คต้น 100 บาท ภาษีหมดอายุ 10-08-25 ผู้ซื้อต้องดำเนินการต่อภาษีเอง กรณีไม่มีป้ายภาษี ผู้ซื้อต้องรับผิดชอบคัดป้ายใหม่เอง กรณีรถติดอายัดจราจร หรือ มีค่าใช้จ่ายคงค้างจากการใช้ทางด่วน/M-flow ผู้ซื้อเป็นผู้รับผิดชอบค่าใช้จ่ายทุกกรณี
B7: 1003 | C7: Toyota | D7: Hilux Revo | E7: Smart Cab | F7: Z Edition Entry | G7: B | H7: 235000 | I7: 19600 | J7: 297000 | K7: 2023 | L7: ผพ-794 | M7: อุบลราชธานี | N7: 2024 | O7: 37113 | P7: RWD | Q7: 2.4 | R7: ดำ | S7: MT | T7: ดีเซล | U7: สุวินทวงศ์ | V7: ถูกยึดคืน
C8: หมายเหตุ: ค่าเช็คต้น 100 บาท ภาษีหมดอายุ 17-05-25 ผู้ซื้อต้องดำเนินการต่อภาษีเอง กรณีไม่มีป้ายภาษี ผู้ซื้อต้องรับผิดชอบคัดป้ายใหม่เอง กรณีรถติดอายัดจราจร หรือ มีค่าใช้จ่ายคงค้างจากการใช้ทางด่วน/M-flow ผู้ซื้อเป็นผู้รับผิดชอบค่าใช้จ่ายทุกกรณี
B9: 1004 | C9: Toyota | D9: Yaris Ativ | F9: Mid | G9: C | H9: 210000 | I9: 18900 | J9: 264000 | K9: 2020 | L9: งจ-7319 | M9: นครราชสีมา | N9: 2020 | O9: 44037 | P9: FWD | Q9: 1.2 | R9: เทา | S9: AT | T9: เบนซิน | U9: สุวินทวงศ์ | V9: ถูกยึดคืน
C10: หมายเหตุ: ค่าเช็คต้น 100 บาท ภาษีหมดอายุ 21-05-25 ผู้ซื้อต้องดำเนินการต่อภาษีเอง กรณีไม่มีป้ายภาษี ผู้ซื้อต้องรับผิดชอบคัดป้ายใหม่เอง กรณีรถติดอายัดจราจร หรือ มีค่าใช้จ่ายคงค้างจากการใช้ทางด่วน/M-flow ผู้ซื้อเป็นผู้รับผิดชอบค่าใช้จ่ายทุกกรณี
B11: 1005 | C11: Toyota | D11: Fortuner | F11: Legender | G11: A | H11: 910000 | I11: 18900 | J11: 1065000 | K11: 2023 | L11: งร-3539 | M11: นครราชสีมา | N11: 2023 | O11: 53183 | P11: RWD | Q11: 2.4 | R11: ขาว ดำ | S11: AT | T11: ดีเซล | U11: สุวินทวงศ์ | V11: ถูกยึดคืน
C12: หมายเหตุ: ค่าเช็คต้น 100 บาท ภาษีหมดอายุ 07-08-25 ผู้ซื้อต้องดำเนินการต่อภาษีเอง กรณีไม่มีป้ายภาษี ผู้ซื้อต้องรับผิดชอบคัดป้ายใหม่เอง กรณีรถติดอายัดจราจร หรือ มีค่าใช้จ่ายคงค้างจากการใช้ทางด่วน/M-flow ผู้ซื้อเป็นผู้รับผิดชอบค่าใช้จ่ายทุกกรณี
B13: 1006 | C13: Toyota | D13: Hilux Revo | E13: Smart Cab | F13: Z Edition Entry | G13: C | H13: 220000 | I13: 19600 | J13: 306000 | K13: 2023 | L13: ยค-1953 | M13: ขอนแก่น | N13: 2023 | O13: 83860 | P13: RWD | Q13: 2.4 | R13: เทา | S13: MT | T13: ดีเซล | U13: สุวินทวงศ์ | V13: ถูกยึดคืน
C14: หมายเหตุ: มีค่าปรับ M-FLOW 330 บาท ค่าเช็คต้น 100 บาท ภาษีหมดอายุ 08-06-24 ผู้ซื้อต้องดำเนินการต่อภาษีเอง กรณีไม่มีป้ายภาษี ผู้ซื้อต้องรับผิดชอบคัดป้ายใหม่เอง กรณีรถติดอายัดจราจร หรือ มีค่าใช้จ่ายคงค้างจากการใช้ทางด่วน/M-flow ผู้ซื้อเป็นผู้รับผิดชอบค่าใช้จ่ายทุกกรณี
B15: 1007 | C15: Toyota | D15: Hilux Revo | E15: Smart Cab | F15: Z Edition Entry | G15: A | H15: 290000 | I15: 19900 | J15: 280000 | K15: 2022 | L15: 3ฒม-2246 | M15: กรุงเทพมหานคร | N15: 2022 | O15: 21599 | P15: RWD | Q15: 2.4 | R15: ขาว | S15: MT | T15: ดีเซล | U15: สุวินทวงศ์ | V15: Op-เช่า
C16: หมายเหตุ: ผู้ซื้อต้องดำเนินการโอนภายใน 45 วัน หากเกินกำหนด ขอเอกสารใหม่ มีค่าใช้จ่าย 2,000 บาท ผู้ขายยกเลิกประกันภัยภาคสมัครใจ และ พรบ. แล้ว กรณีรถติดอายัดในเรื่องของจราจร ผู้ซื้อเป็นผู้รับผิดชอบค่าใช้จ่ายทุกกรณี ค่าดำเนินการอื่น 5,000 บาท (ไม่รวม Vat) ไม่มีแผ่นป้ายภาษี ผู้ซื้อดำเนินการคัดป้ายใหม่เอง
B17: 1008 | C17: Toyota | D17: Yaris | F17: Sport | G17: A | H17: 320000 | I17: 18900 | J17: 384000 | K17: 2023 | L17: 5ขน-7286 | M17: กรุงเทพมหานคร | N17: 2024 | O17: 6066 | P17: FWD | Q17: 1.2 | R17: ขาว | S17: AT | T17: เบนซิน | U17: สุวินทวงศ์ | V17: ถูกยึดคืน
C18: หมายเหตุ: ค่าเช็คต้น 100 บาท ภาษีหมดอายุ 28-06-25 ผู้ซื้อต้องดำเนินการต่อภาษีเอง กรณีไม่มีป้ายภาษี ผู้ซื้อต้องรับผิดชอบคัดป้ายใหม่เอง กรณีรถติดอายัดจราจร หรือ มีค่าใช้จ่ายคงค้างจากการใช้ทางด่วน/M-flow ผู้ซื้อเป็นผู้รับผิดชอบค่าใช้จ่ายทุกกรณี
B19: 1009 | C19: Toyota | D19: Hilux Revo | E19: Double Cab | F19: Prerunner J Plus | G19: C | H19: 320000 | I19: 19600 | J19: 348000 | K19: 2018 | L19: 8กณ-7713 | M19: กรุงเทพมหานคร | N19: 2018 | O19: 152325 | P19: RWD | Q19: 2.4 | R19: ขาว | S19: MT | T19: ดีเซล | U19: สุวินทวงศ์ | V19: ถูกยึดคืน
C20: หมายเหตุ: ค่าเช็คต้น 100 บาท ภาษีหมดอายุ 30-11-24 ผู้ซื้อต้องดำเนินการต่อภาษีเอง กรณีไม่มีป้ายภาษี ผู้ซื้อต้องรับผิดชอบคัดป้ายใหม่เอง กรณีรถติดอายัดจราจร หรือ มีค่าใช้จ่ายคงค้างจากการใช้ทางด่วน/M-flow ผู้ซื้อเป็นผู้รับผิดชอบค่าใช้จ่ายทุกกรณี
B21: 1010 | C21: Toyota | D21: Corolla Altis | F21: G | G21: E | H21: 300000 | I21: 21594 | J21: 358000 | K21: 2020 | L21: 1ขผ-3571 | M21: กรุงเทพมหานคร | N21: 2021 | O21: 144019 | P21: FWD | Q21: 1.6 | R21: เทา | S21: AT | T21: เบนซิน | U21: สุวินทวงศ์ | V21: Op-เช่า
C22: หมายเหตุ: บังคับโอนกรรมสิทธิ์ผ่านผู้ขาย ค่าโอนกรรมสิทธิ์ 3000 บาท ค่าภาษีเรียกเก็บคืนผู้ขาย 3,594 บาท
B23: 1011 | C23: Toyota | D23: Camry | F23: G | G23: B | H23: 560000 | I23: 18000 | J23: 0 | K23: 2019 | L23: 8กส-4474 | M23: กรุงเทพมหานคร | N23: 2019 | O23: 119787 | P23: FWD | Q23: 2 | R23: เทา | S23: AT | T23: เบนซิน | U23: สุวินทวงศ์ | V23: Op-เช่า
C24: หมายเหตุ: โอนกรรมสิทธิ์ผ่านผู้ขาย ค่าโอน 3000 บาท กรณีไม่มีป้ายภาษี ผู้ซื้อต้องรับผิดชอบคัดป้ายใหม่เอง
B25: 1012 | C25: Toyota | D25: Vios | F25: Entry | G25: D | H25: 260000 | I25: 18000 | J25: 0 | K25: 2021 | L25: 1ขฬ-8600 | M25: กรุงเทพมหานคร | N25: 2021 | O25: 74775 | P25: FWD | Q25: 1.5 | R25: เทา | S25: AT | T25: เบนซิน | U25: สุวินทวงศ์ | V25: Op-เช่า
C26: หมายเหตุ: โอนกรรมสิทธิ์ผ่านผู้ขาย ค่าโอน 3000 บาท กรณีไม่มีป้ายภาษี ผู้ซื้อต้องรับผิดชอบคัดป้ายใหม่เอง
B27: 1013 | C27: Toyota | D27: Hilux Revo | E27: Double Cab | F27: Z Edition Entry | G27: B | H27: 390000 | I27: 18000 | J27: 0 | K27: 2023 | L27: 4ขจ-3771 | M27: กรุงเทพมหานคร | N27: 2023 | O27: 75818 | P27: RWD | Q27: 2.4 | R27: เทา | S27: MT | T27: ดีเซล | U27: สุวินทวงศ์ | V27: Op-เช่า
C28: หมายเหตุ: โอนกรรมสิทธิ์ผ่านผู้ขาย ค่าโอน 3000 บาท กรณีไม่มีป้ายภาษี ผู้ซื้อต้องรับผิดชอบคัดป้ายใหม่เอง
B29: 1014 | C29: Toyota | D29: Fortuner | F29: V | G29: C | H29: 760000 | I29: 18000 | J29: 760000 | K29: 2019 | L29: 9กฐ-4197 | M29: กรุงเทพมหานคร | N29: 2019 | O29: 184612 | P29: 4WD | Q29: 2.4 | R29: ดำ | S29: AT | T29: ดีเซล | U29: สุวินทวงศ์
C30: หมายเหตุ: บังคับโอน 2 ต่อ ค่าโอนกรรมสิทธิ์ 3000 บาท กรณีติดอายัดจราจรผู้ซื้อเป็นผู้รับผิดชอบทุกกรณี
B31: 1015 | C31: Toyota | D31: Hilux Revo | E31: Smart Cab | F31: High | G31: D | H31: 480000 | I31: 19600 | J31: 587000 | K31: 2022 | L31: ผธ-3047 | M31: นครศรีธรรมราช | N31: 2022 | O31: 33825 | P31: 4WD | Q31: 2.8 | R31: เทา | S31: MT | T31: ดีเซล | U31: สุวินทวงศ์ | V31: ถูกยึดคืน
C32: หมายเหตุ: ค่าเช็คต้น 100 บาท ภาษีหมดอายุ 07-12-24 ผู้ซื้อต้องดำเนินการต่อภาษีเอง กรณีไม่มีป้ายภาษี ผู้ซื้อต้องรับผิดชอบคัดป้ายใหม่เอง กรณีรถติดอายัดจราจร หรือ มีค่าใช้จ่ายคงค้างจากการใช้ทางด่วน/M-flow ผู้ซื้อเป็นผู้รับผิดชอบค่าใช้จ่ายทุกกรณี
B33: 1016 | C33: Toyota | D33: Veloz | F33: Premium | G33: A | H33: 485000 | I33: 15600 | J33: 581000 | K33: 2023 | L33: 3ขฮ-3040 | M33: กรุงเทพมหานคร | N33: 2023 | O33: 29085 | P33: FWD | Q33: 1.5 | R33: ดำ | S33: AT | T33: เบนซิน | U33: สุวินทวงศ์ | V33: ถูกยึดคืน
C34: หมายเหตุ: ค่าเช็คต้น 100 บาท ภาษีหมดอายุ 07-03-25 ผู้ซื้อต้องดำเนินการต่อภาษีเอง กรณีไม่มีป้ายภาษี ผู้ซื้อต้องรับผิดชอบคัดป้ายใหม่เอง กรณีรถติดอายัดจราจร หรือ มีค่าใช้จ่ายคงค้างจากการใช้ทางด่วน/M-flow ผู้ซื้อเป็นผู้รับผิดชอบค่าใช้จ่ายทุกกรณี
B35: 1017 | C35: Toyota | D35: Hilux Revo | E35: Smart Cab | F35: Z Edition Entry | G35: B | H35: 235000 | I35: 15600 | J35: 317000 | K35: 2023 | L35: บว-2404 | M35: กำแพงเพชร | N35: 2023 | O35: 6155 | P35: RWD | Q35: 2.4 | R35: เทา | S35: MT | T35: ดีเซล | U35: สุวินทวงศ์ | V35: ถูกยึดคืน
C36: หมายเหตุ: ค่าเช็คต้น 100 บาท ภาษีหมดอายุ 29-08-24 ผู้ซื้อต้องดำเนินการต่อภาษีเอง กรณีไม่มีป้ายภาษี ผู้ซื้อต้องรับผิดชอบคัดป้ายใหม่เอง กรณีรถติดอายัดจราจร หรือ มีค่าใช้จ่ายคงค้างจากการใช้ทางด่วน/M-flow ผู้ซื้อเป็นผู้รับผิดชอบค่าใช้จ่ายทุกกรณี
B37: 1018 | C37: Toyota | D37: Hilux Revo | E37: Double Cab | F37: Prerunner E | G37: C | H37: 340000 | I37: 15600 | J37: 396000 | K37: 2019 | L37: กพ-7136 | M37: ฉะเชิงเทรา | N37: 2020 | O37: 98146 | P37: RWD | Q37: 2.4 | R37: ขาว | S37: MT | T37: ดีเซล | U37: สุวินทวงศ์ | V37: ถูกยึดคืน
C38: หมายเหตุ: ค่าเช็คต้น 100 บาท ภาษีหมดอายุ 31-07-24 ผู้ซื้อต้องดำเนินการต่อภาษีเอง กรณีไม่มีป้ายภาษี ผู้ซื้อต้องรับผิดชอบคัดป้ายใหม่เอง กรณีรถติดอายัดจราจร หรือ มีค่าใช้จ่ายคงค้างจากการใช้ทางด่วน/M-flow ผู้ซื้อเป็นผู้รับผิดชอบค่าใช้จ่ายทุกกรณี
B39: 1019 | C39: Toyota | D39: Fortuner | F39: V | G39: A | H39: 780000 | I39: 14400 | J39: 756000 | K39: 2019 | L39: 9กน-3100 | M39: กรุงเทพมหานคร | N39: 2020 | O39: 132267 | P39: 4WD | Q39: 2.8 | R39: เทา | S39: AT | T39: ดีเซล | U39: สุวินทวงศ์ | V39: Op-เช่า
C40: หมายเหตุ: กรณีภาษีหมดอายุ ผู้ซื้อต้องดำเนินการต่อภาษีเอง กรณีไม่มีป้ายภาษี ผู้ซื้อต้องรับผิดชอบคัดป้ายใหม่เอง กรณีรถติดอายัดจราจร หรือ มีค่าใช้จ่ายคงค้างจากการใช้ทางด่วน/M-flow ผู้ซื้อเป็นผู้รับผิดชอบค่าใช้จ่ายทุกกรณี
...

Sheet 20012025
C1: 45677 | D1: 79 | E1: =COUNTA(B:B)-1 -> 79
A2: รูปภาพ | B2: ลำดับที่ | C2: ยี่ห้อ | D2: รุ่น | E2: ประเภทรถกระบะ | F2: รุ่นย่อย | G2: เกรด | H2: ราคาเริ่มต้น (ไม่รวมvat) | I2: ค่าธรรมเนียม (ไม่รวมvat) | J2: ราคาสูงสุด | K2: ปีที่ผลิต | L2: ป้ายทะเบียนรถ | M2: จังหวัด | N2: ปีที่จดทะเบียน | O2: เลขไมล์ (กม.) | P2: ระบบขับเคลื่อน | Q2: ความจุ (CC) | R2: สี | S2: ระบบเกียร์ | T2: เชื้อเพลิง | U2: สถานที่จอดรถ | V2: ประเภทรถประมูล
B3: 1001 | C3: Toyota | D3: Hilux Champ | E3: Single Cab | F3: Attractive Package | G3: C | H3: 330000 | I3: 20100 | J3: 396000 | K3: 2024 | L3: ยง-1452 | M3: ขอนแก่น | N3: 2024 | O3: 31112 | P3: RWD | Q3: 2.4 | R3: เทา | S3: AT | T3: ดีเซล | U3: สุวินทวงศ์ | V3: ถูกยึดคืน
C4: หมายเหตุ: ค่าเช็คต้น 100 บาท ภาษีหมดอายุ 24-05-25 ผู้ซื้อต้องดำเนินการต่อภาษีเอง กรณีไม่มีป้ายภาษี ผู้ซื้อต้องรับผิดชอบคัดป้ายใหม่เอง กรณีรถติดอายัดจราจร หรือ มีค่าใช้จ่ายคงค้างจากการใช้ทางด่วน/M-flow ผู้ซื้อเป็นผู้รับผิดชอบค่าใช้จ่ายทุกกรณี
B5: 1002 | C5: Toyota | D5: Hilux Revo | E5: Double Cab | F5: Prerunner Mid | G5: A | H5: 460000 | I5: 19600 | J5: 614000 | K5: 2022 | L5: ขก-6599 | M5: นครสวรรค์ | N5: 2022 | O5: 52090 | P5: RWD | Q5: 2.4 | R5: ขาว | S5: AT | T5: ดีเซล | U5: สุวินทวงศ์ | V5: ถูกยึดคืน
C6: หมายเหตุ: ค่าเช็คต้น 100 บาท ภาษีหมดอายุ 01-07-25 ผู้ซื้อต้องดำเนินการต่อภาษีเอง กรณีไม่มีป้ายภาษี ผู้ซื้อต้องรับผิดชอบคัดป้ายใหม่เอง กรณีรถติดอายัดจราจร หรือ มีค่าใช้จ่ายคงค้างจากการใช้ทางด่วน/M-flow ผู้ซื้อเป็นผู้รับผิดชอบค่าใช้จ่ายทุกกรณี
B7: 1003 | C7: Toyota | D7: Fortuner | F7: Legender | G7: D | H7: 840000 | I7: 18900 | J7: 940000 | K7: 2021 | L7: งธ-750 | M7: นครราชสีมา | N7: 2021 | O7: 27886 | P7: RWD | Q7: 2.4 | R7: ขาว ดำ | S7: AT | T7: ดีเซล | U7: สุวินทวงศ์ | V7: ถูกยึดคืน
C8: หมายเหตุ: มีค่าปรับ M-FLOW 660 บาท ค่าเช็คต้น 100 บาท ภาษีหมดอายุ 26-08-22 ผู้ซื้อต้องดำเนินการต่อภาษีเอง กรณีไม่มีป้ายภาษี ผู้ซื้อต้องรับผิดชอบคัดป้ายใหม่เอง กรณีรถติดอายัดจราจร หรือ มีค่าใช้จ่ายคงค้างจากการใช้ทางด่วน/M-flow ผู้ซื้อเป็นผู้รับผิดชอบค่าใช้จ่ายทุกกรณี
B9: 1004 | C9: Toyota | D9: Hilux Revo | E9: Single Cab | F9: Entry | G9: B | H9: 340000 | I9: 18900 | J9: 555000 | K9: 2023 | L9: ผน-5388 | M9: ระยอง | N9: 2024 | O9: 70353 | P9: 4WD | Q9: 2.8 | R9: เทา | S9: AT | T9: ดีเซล | U9: สุวินทวงศ์ | V9: ถูกยึดคืน
C10: หมายเหตุ: ค่าเช็คต้น 100 บาท ภาษีหมดอายุ 09-02-25 ผู้ซื้อต้องดำเนินการต่อภาษีเอง กรณีไม่มีป้ายภาษี ผู้ซื้อต้องรับผิดชอบคัดป้ายใหม่เอง กรณีรถติดอายัดจราจร หรือ มีค่าใช้จ่ายคงค้างจากการใช้ทางด่วน/M-flow ผู้ซื้อเป็นผู้รับผิดชอบค่าใช้จ่ายทุกกรณี
B11: 1005 | C11: Toyota | D11: Hilux Revo | E11: Double Cab | F11: Prerunner E Plus | G11: E | H11: 320000 | I11: 17400 | J11: 396000 | K11: 2020 | L11: 9กษ-6108 | M11: กรุงเทพมหานคร | N11: 2020 | O11: 70867 | P11: RWD | Q11: 2.4 | R11: ดำ | S11: MT | T11: ดีเซล | U11: สุวินทวงศ์ | V11: ถูกยึดคืน
C12: หมายเหตุ: ค่าเช็คต้น 100 บาท ภาษีหมดอายุ 10-04-25 ผู้ซื้อต้องดำเนินการต่อภาษีเอง กรณีไม่มีป้ายภาษี ผู้ซื้อต้องรับผิดชอบคัดป้ายใหม่เอง กรณีรถติดอายัดจราจร หรือ มีค่าใช้จ่ายคงค้างจากการใช้ทางด่วน/M-flow ผู้ซื้อเป็นผู้รับผิดชอบค่าใช้จ่ายทุกกรณี
B13: 1006 | C13: Toyota | D13: Yaris | F13: High | G13: C | H13: 210000 | I13: 18400 | J13: 262000 | K13: 2019 | L13: งษ-1245 | M13: ชลบุรี | N13: 2020 | O13: 58509 | P13: FWD | Q13: 1.2 | R13: ขาว | S13: AT | T13: เบนซิน | U13: สุวินทวงศ์ | V13: ถูกยึดคืน
C14: หมายเหตุ: มีค่าปรับ M-FLOW 1,980 บาท ค่าเช็คต้น 100 บาท ภาษีหมดอายุ 17-06-25 ผู้ซื้อต้องดำเนินการต่อภาษีเอง กรณีไม่มีป้ายภาษี ผู้ซื้อต้องรับผิดชอบคัดป้ายใหม่เอง กรณีรถติดอายัดจราจร หรือ มีค่าใช้จ่ายคงค้างจากการใช้ทางด่วน/M-flow ผู้ซื้อเป็นผู้รับผิดชอบค่าใช้จ่ายทุกกรณี
B15: 1007 | C15: Toyota | D15: Hilux Revo | E15: Smart Cab | F15: Prerunner G | G15: E | H15: 230000 | I15: 17400 | J15: 267000 | K15: 2015 | L15: 2ฒฉ-5989 | M15: กรุงเทพมหานคร | N15: 2017 | O15: 79119 | P15: RWD | Q15: 2.8 | R15: ดำ | S15: MT | T15: ดีเซล | U15: สุวินทวงศ์ | V15: ถูกยึดคืน
C16: หมายเหตุ: มีค่าปรับ M-FLOW 330 บาท ค่าเช็คต้น 100 บาท ภาษีหมดอายุ 22-11-24 ผู้ซื้อต้องดำเนินการต่อภาษีเอง กรณีไม่มีป้ายภาษี ผู้ซื้อต้องรับผิดชอบคัดป้ายใหม่เอง กรณีรถติดอายัดจราจร หรือ มีค่าใช้จ่ายคงค้างจากการใช้ทางด่วน/M-flow ผู้ซื้อเป็นผู้รับผิดชอบค่าใช้จ่ายทุกกรณี
B17: 1008 | C17: Toyota | D17: Hilux Revo | E17: Smart Cab | F17: Z Edition Entry | G17: B | H17: 272000 | I17: 15600 | J17: 351000 | K17: 2024 | L17: ผก-4504 | M17: พระนครศรีอยุธยา | N17: 2024 | O17: 21650 | P17: RWD | Q17: 2.4 | R17: เทา | S17: MT | T17: ดีเซล | U17: สุวินทวงศ์ | V17: ถูกยึดคืน
C18: หมายเหตุ: เลขเครื่องเป็นสนิม ขายตามสภาพ ค่าเช็คต้น 100 บาท ภาษีหมดอายุ 15-05-25 ผู้ซื้อต้องดำเนินการต่อภาษีเอง กรณีไม่มีป้ายภาษี ผู้ซื้อต้องรับผิดชอบคัดป้ายใหม่เอง กรณีรถติดอายัดจราจร หรือ มีค่าใช้จ่ายคงค้างจากการใช้ทางด่วน/M-flow ผู้ซื้อเป็นผู้รับผิดชอบค่าใช้จ่ายทุกกรณี
B19: 1009 | C19: Toyota | D19: Alphard | F19: HV | G19: C | H19: 1320000 | I19: 16000 | J19: 1400000 | K19: 2017 | L19: 9กฆ-2357 | M19: กรุงเทพมหานคร | N19: 2017 | O19: 188292 | P19: FWD | Q19: 2.5 | R19: ดำ | S19: AT | T19: ไฮบริด | U19: สุวินทวงศ์
C20: หมายเหตุ: ค่าโอนกรรมสิทธิ์ 3000 บาท กรณีติดอายัดจราจรผู้ซื้อเป็นผู้รับผิดชอบทุกกรณี
B21: 1010 | C21: Honda | D21: Civic | F21: E i-VTEC | G21: A+ | H21: 442000 | I21: 15000 | J21: 430000 | K21: 2020 | L21: 9กฬ-4007 | M21: กรุงเทพมหานคร | N21: 2020 | O21: 93450 | P21: FWD | Q21: 1.8 | R21: เทา | S21: AT | T21: เบนซิน | U21: สุวินทวงศ์ | V21: Op-เช่า
C22: หมายเหตุ: หากเอกสารหมดอายุ ขอเอกสารใหม่มีค่าใช้จ่าย 2000 บาท
B23: 1011 | C23: Mitsubishi | D23: Triton | E23: Extra Cab | F23: GLX | G23: F | H23: 50000 | I23: 10000 | J23: 50000 | K23: 2012 | L23: 2ฒม-8433 | M23: กรุงเทพมหานคร | N23: 2012 | O23: 451619 | P23: RWD | Q23: 2.5 | R23: เทา | S23: MT | T23: ดีเซล | U23: สุวินทวงศ์
C24: หมายเหตุ: เลขเครื่องเป็นสนิม แซสซีเป็นสนิม เบาะโดยสารดัดแปลงมา ขายตามสภาพ ไม่มีแผ่นป้ายทะเบียนหลัง ผู้ซื้อดำเนินการคัดป้ายใหม่เอง กรณีเอกสารหมดอายุหรือสูญหาย ขอเอกสารใหม่มีค่าใช้จ่าย 500 บาท
B25: 1012 | C25: Honda | D25: Jazz | F25: S i-VTEC | G25: E | H25: 180000 | I25: 10000 | J25: 230000 | K25: 2016 | L25: 5กท-9451 | M25: กรุงเทพมหานคร | N25: 2016 | O25: 156873 | P25: FWD | Q25: 1.5 | R25: ขาว | S25: AT | T25: เบนซิน | U25: สุวินทวงศ์
C26: หมายเหตุ: กรณีเอกสารหมดอายุหรือสูญหาย ขอเอกสารใหม่มีค่าใช้จ่าย 500 บาท
B27: 1013 | C27: Toyota | D27: Hilux Vigo | E27: Extra Cab | F27: J | G27: F | H27: 50000 | I27: 10000 | J27: 62000 | K27: 2009 | L27: บท-8316 | M27: นครพนม | N27: 2009 | O27: 339626 | P27: RWD | Q27: 2.5 | R27: ขาว | S27: MT | T27: ดีเซล | U27: สุวินทวงศ์
C28: หมายเหตุ: แซสซีเป็นสนิม ขายตามสภาพ มีค่าปรับ M-flow 990 บาท กรณีเอกสารหมดอายุหรือสูญหาย ขอเอกสารใหม่มีค่าใช้จ่าย 500 บาท
B29: 1014 | C29: Isuzu | D29: D-Max | E29: Double Cab | F29: Hi-Lander L DA | G29: A | H29: 440000 | I29: 10000 | J29: 545000 | K29: 2022 | L29: กว-7605 | M29: นครปฐม | N29: 2022 | O29: 18592 | P29: RWD | Q29: 1.9 | R29: เทา | S29: MT | T29: ดีเซล | U29: สุวินทวงศ์
C30: หมายเหตุ: (KA) กรณีเอกสารหมดอายุหรือสูญหาย ขอเอกสารใหม่มีค่าใช้จ่าย 500 บาท
B31: 1015 | C31: Nissan | D31: Sylphy | F31: V | G31: F | H31: 100000 | I31: 10000 | J31: 120000 | K31: 2014 | L31: 2ขช-268 | M31: กรุงเทพมหานคร | N31: 2014 | O31: 206281 | P31: FWD | Q31: 1.6 | R31: ขาว | S31: AT | T31: เบนซิน | U31: สุวินทวงศ์
C32: หมายเหตุ: รถน้ำท่วม ขายตามสภาพ กรณีเอกสารหมดอายุหรือสูญหาย ขอเอกสารใหม่มีค่าใช้จ่าย 500 บาท
B33: 1016 | C33: Toyota | D33: Fortuner | F33: V | G33: E | H33: 140000 | I33: 10000 | J33: 242000 | K33: 2006 | L33: ญท-3528 | M33: กรุงเทพมหานคร | N33: 2006 | O33: 232875 | P33: 4WD | Q33: 3 | R33: ดำ | S33: AT | T33: ดีเซล | U33: สุวินทวงศ์
C34: หมายเหตุ: มีค่าปรับ M-flow 1320 บาท กรณีเอกสารหมดอายุหรือสูญหาย ขอเอกสารใหม่มีค่าใช้จ่าย 500 บาท
B35: 1017 | C35: Isuzu | D35: D-Max | E35: Double Cab | F35: Hi-Lander Z | G35: E | H35: 160000 | I35: 10000 | J35: 206000 | K35: 2012 | L35: ฆห-9050 | M35: กรุงเทพมหานคร | N35: 2012 | O35: 243389 | P35: RWD | Q35: 2.5 | R35: ขาว | S35: MT | T35: ดีเซล | U35: สุวินทวงศ์
C36: หมายเหตุ: เลขเครื่องเป็นสนิม ขายตามสภาพ รถติดอายัดจราจร มีใบสั่ง 1 ใบ ปรับ 1000 บาท กรณีเอกสารหมดอายุหรือสูญหาย ขอเอกสารใหม่มีค่าใช้จ่าย 500 บาท
B37: 1018 | C37: Honda | D37: Civic | F37: E i-VTEC | G37: E | H37: 300000 | I37: 10000 | J37: 340000 | K37: 2018 | L37: กต-9803 | M37: สระแก้ว | N37: 2018 | O37: 140796 | P37: FWD | Q37: 1.8 | R37: เทา | S37: AT | T37: เบนซิน | U37: สุวินทวงศ์
C38: หมายเหตุ: กรณีเอกสารหมดอายุหรือสูญหาย ขอเอกสารใหม่มีค่าใช้จ่าย 500 บาท
B39: 1019 | C39: Mitsubishi | D39: Triton | E39: Smart Cab | F39: GLS Plus | G39: C | H39: 210000 | I39: 10000 | J39: 284000 | K39: 2018 | L39: 2ฒษ-1301 | M39: กรุงเทพมหานคร | N39: 2019 | O39: 54018 | P39: RWD | Q39: 2.4 | R39: ขาว | S39: MT | T39: ดีเซล | U39: สุวินทวงศ์
C40: หมายเหตุ: เลขถังเป็นสนิม ขายตามสภาพ กรณีเอกสารหมดอายุหรือสูญหาย ขอเอกสารใหม่มีค่าใช้จ่าย 500 บาท
...

Sheet 23012025
C1: 45680 | D1: 92 | E1: =COUNTA(B:B)-1 -> 92
A2: รูปภาพ | B2: ลำดับที่ | C2: ยี่ห้อ | D2: รุ่น | E2: ประเภทรถกระบะ | F2: รุ่นย่อย | G2: เกรด | H2: ราคาเริ่มต้น (ไม่รวมvat) | I2: ค่าธรรมเนียม (ไม่รวมvat) | J2: ราคาสูงสุด | K2: ปีที่ผลิต | L2: ป้ายทะเบียนรถ | M2: จังหวัด | N2: ปีที่จดทะเบียน | O2: เลขไมล์ (กม.) | P2: ระบบขับเคลื่อน | Q2: ความจุ (CC) | R2: สี | S2: ระบบเกียร์ | T2: เชื้อเพลิง | U2: สถานที่จอดรถ | V2: ประเภทรถประมูล
B3: 1001 | C3: Toyota | D3: Hilux Revo | E3: Double Cab | F3: Prerunner Entry | G3: A+ | H3: 460000 | I3: 19600 | J3: 620000 | K3: 2022 | L3: กร-2199 | M3: ฉะเชิงเทรา | N3: 2023 | O3: 16699 | P3: FWD | Q3: 2.4 | R3: ขาว | S3: AT | T3: ดีเซล | U3: สุวินทวงศ์ | V3: ถูกยึดคืน
C4: หมายเหตุ: ค่าเช็คต้น 100 บาท ภาษีหมดอายุ 07-07-25 ผู้ซื้อต้องดำเนินการต่อภาษีเอง กรณีไม่มีป้ายภาษี ผู้ซื้อต้องรับผิดชอบคัดป้ายใหม่เอง กรณีรถติดอายัดจราจร หรือ มีค่าใช้จ่ายคงค้างจากการใช้ทางด่วน/M-flow ผู้ซื้อเป็นผู้รับผิดชอบค่าใช้จ่ายทุกกรณี
B5: 1002 | C5: Toyota | D5: Yaris | F5: Sport | G5: A | H5: 250000 | I5: 20600 | J5: 298000 | K5: 2020 | L5: กน-2536 | M5: เพชรบูรณ์ | N5: 2021 | O5: 91040 | P5: RWD | Q5: 1.2 | R5: ขาว | S5: AT | T5: เบนซิน | U5: สุวินทวงศ์ | V5: ถูกยึดคืน
C6: หมายเหตุ: ค่าเช็คต้น 100 บาท ภาษีหมดอายุ 20-01-24 ผู้ซื้อต้องดำเนินการต่อภาษีเอง กรณีไม่มีป้ายภาษี ผู้ซื้อต้องรับผิดชอบคัดป้ายใหม่เอง กรณีรถติดอายัดจราจร หรือ มีค่าใช้จ่ายคงค้างจากการใช้ทางด่วน/M-flow ผู้ซื้อเป็นผู้รับผิดชอบค่าใช้จ่ายทุกกรณี
B7: 1003 | C7: Toyota | D7: Hilux Revo | E7: Double Cab | F7: Z Edition Entry | G7: A | H7: 310000 | I7: 19600 | J7: 401000 | K7: 2023 | L7: กพ-1290 | M7: กระบี่ | N7: 2023 | O7: 26851 | P7: RWD | Q7: 2.4 | R7: เทา | S7: MT | T7: ดีเซล | U7: สุวินทวงศ์ | V7: ถูกยึดคืน
C8: หมายเหตุ: ค่าเช็คต้น 100 บาท ภาษีหมดอายุ 31-03-25 ผู้ซื้อต้องดำเนินการต่อภาษีเอง กรณีไม่มีป้ายภาษี ผู้ซื้อต้องรับผิดชอบคัดป้ายใหม่เอง กรณีรถติดอายัดจราจร หรือ มีค่าใช้จ่ายคงค้างจากการใช้ทางด่วน/M-flow ผู้ซื้อเป็นผู้รับผิดชอบค่าใช้จ่ายทุกกรณี
B9: 1004 | C9: Toyota | D9: Corolla Cross | F9: Hybrid Premium Safety | G9: B | H9: 580000 | I9: 18400 | J9: 598000 | K9: 2020 | L9: ขธ-7818 | M9: ระยอง | N9: 2021 | O9: 94006 | P9: FWD | Q9: 1.8 | R9: แดง | S9: AT | T9: ไฮบริด | U9: สุวินทวงศ์ | V9: ถูกยึดคืน
C10: หมายเหตุ: ค่าเช็คต้น 100 บาท ภาษีหมดอายุ 25-04-24 ผู้ซื้อต้องดำเนินการต่อภาษีเอง กรณีไม่มีป้ายภาษี ผู้ซื้อต้องรับผิดชอบคัดป้ายใหม่เอง กรณีรถติดอายัดจราจร หรือ มีค่าใช้จ่ายคงค้างจากการใช้ทางด่วน/M-flow ผู้ซื้อเป็นผู้รับผิดชอบค่าใช้จ่ายทุกกรณี
B11: 1005 | C11: Toyota | D11: Hilux Revo | E11: Smart Cab | F11: Prerunner Mid | G11: C | H11: 320000 | I11: 20400 | J11: 398000 | K11: 2022 | L11: ผค-4324 | M11: พิษณุโลก | N11: 2023 | O11: 93370 | P11: RWD | Q11: 2.4 | R11: เทา | S11: MT | T11: ดีเซล | U11: สุวินทวงศ์ | V11: ถูกยึดคืน
C12: หมายเหตุ: ค่าเช็คต้น 100 บาท ภาษีหมดอายุ 01-02-25 ผู้ซื้อต้องดำเนินการต่อภาษีเอง กรณีไม่มีป้ายภาษี ผู้ซื้อต้องรับผิดชอบคัดป้ายใหม่เอง กรณีรถติดอายัดจราจร หรือ มีค่าใช้จ่ายคงค้างจากการใช้ทางด่วน/M-flow ผู้ซื้อเป็นผู้รับผิดชอบค่าใช้จ่ายทุกกรณี
B13: 1006 | C13: Toyota | D13: Hilux Revo | E13: Single Cab | F13: Entry | G13: E | H13: 260000 | I13: 18200 | J13: 290000 | K13: 2023 | L13: 3ฒศ-3491 | M13: กรุงเทพมหานคร | N13: 2023 | O13: 128535 | P13: RWD | Q13: 2.8 | R13: ขาว | S13: MT | T13: ดีเซล | U13: สุวินทวงศ์ | V13: ถูกยึดคืน
C14: หมายเหตุ: รถลุยน้ำมา เลขเครื่องเป็นสนิม ขายตามสภาพ ค่าเช็คต้น 100 บาท ภาษีหมดอายุ 10-07-24 ผู้ซื้อต้องดำเนินการต่อภาษีเอง กรณีไม่มีป้ายภาษี ผู้ซื้อต้องรับผิดชอบคัดป้ายใหม่เอง กรณีรถติดอายัดจราจร หรือ มีค่าใช้จ่ายคงค้างจากการใช้ทางด่วน/M-flow ผู้ซื้อเป็นผู้รับผิดชอบค่าใช้จ่ายทุกกรณี
B15: 1007 | C15: Toyota | D15: Yaris Ativ | F15: Premium Luxury | G15: C | H15: 300000 | I15: 19600 | J15: 372000 | K15: 2022 | L15: ขฉ-3401 | M15: สุราษฎร์ธานี | N15: 2022 | O15: 95500 | P15: FWD | Q15: 1.2 | R15: ขาว | S15: AT | T15: เบนซิน | U15: สุวินทวงศ์ | V15: ถูกยึดคืน
C16: หมายเหตุ: ค่าเช็คต้น 100 บาท ภาษีหมดอายุ 04-10-24 ผู้ซื้อต้องดำเนินการต่อภาษีเอง กรณีไม่มีป้ายภาษี ผู้ซื้อต้องรับผิดชอบคัดป้ายใหม่เอง กรณีรถติดอายัดจราจร หรือ มีค่าใช้จ่ายคงค้างจากการใช้ทางด่วน/M-flow ผู้ซื้อเป็นผู้รับผิดชอบค่าใช้จ่ายทุกกรณี
B17: 1008 | C17: Toyota | D17: Hilux Revo | E17: Smart Cab | F17: Z Edition Entry | G17: C | H17: 240000 | I17: 15600 | J17: 319000 | K17: 2023 | L17: 3ฒร-5903 | M17: กรุงเทพมหานคร | N17: 2023 | O17: 19382 | P17: RWD | Q17: 2.4 | R17: เทา | S17: MT | T17: ดีเซล | U17: สุวินทวงศ์ | V17: ถูกยึดคืน
C18: หมายเหตุ: ค่าเช็คต้น 100 บาท ภาษีหมดอายุ 15-03-25 ผู้ซื้อต้องดำเนินการต่อภาษีเอง กรณีไม่มีป้ายภาษี ผู้ซื้อต้องรับผิดชอบคัดป้ายใหม่เอง กรณีรถติดอายัดจราจร หรือ มีค่าใช้จ่ายคงค้างจากการใช้ทางด่วน/M-flow ผู้ซื้อเป็นผู้รับผิดชอบค่าใช้จ่ายทุกกรณี
B19: 1009 | C19: Honda | D19: Civic | F19: EL | G19: C | H19: 440000 | I19: 22197 | J19: 446000 | K19: 2020 | L19: 1ขน-6602 | M19: กรุงเทพมหานคร | N19: 2020 | O19: 129649 | P19: FWD | Q19: 1.8 | R19: เทา | S19: AT | T19: เบนซิน | U19: สุวินทวงศ์ | V19: Op-เช่า
C20: หมายเหตุ: บังคับโอนกรรมสิทธิ์ผ่านผู้ขาย ค่าโอนกรรมสิทธิ์ 3000 บาท ค่าภาษีเรียกเก็บคืนผู้ขาย 4,197 บาท
B21: 1010 | C21: Toyota | D21: Alphard | F21: HV | G21: C | H21: 1320000 | I21: 16000 | J21: 1340000 | K21: 2017 | L21: 9กฆ-2357 | M21: กรุงเทพมหานคร | N21: 2017 | O21: 188292 | P21: FWD | Q21: 2.5 | R21: ดำ | S21: AT | T21: ไฮบริด | U21: สุวินทวงศ์
C22: หมายเหตุ: ค่าโอนกรรมสิทธิ์ 3000 บาท กรณีติดอายัดจราจรผู้ซื้อเป็นผู้รับผิดชอบทุกกรณี
B23: 1011 | C23: Toyota | D23: Hilux Revo | E23: Double Cab | F23: Z Edition Entry | G23: B | H23: 390000 | I23: 18000 | J23: 360000 | K23: 2023 | L23: 4ขจ-3771 | M23: กรุงเทพมหานคร | N23: 2023 | O23: 75818 | P23: RWD | Q23: 2.4 | R23: เทา | S23: MT | T23: ดีเซล | U23: สุวินทวงศ์ | V23: Op-เช่า
C24: หมายเหตุ: โอนกรรมสิทธิ์ผ่านผู้ขาย ค่าโอน 3000 บาท กรณีไม่มีป้ายภาษี ผู้ซื้อต้องรับผิดชอบคัดป้ายใหม่เอง
B25: 1012 | C25: Toyota | D25: Vios | F25: Mid | G25: A | H25: 300000 | I25: 18000 | J25: 326000 | K25: 2020 | L25: 1ขท-340 | M25: กรุงเทพมหานคร | N25: 2020 | O25: 110445 | P25: FWD | Q25: 1.5 | R25: เทา | S25: AT | T25: เบนซิน | U25: สุวินทวงศ์ | V25: Op-เช่า
C26: หมายเหตุ: โอนกรรมสิทธิ์ผ่านผู้ขาย ค่าโอน 3000 บาท กรณีไม่มีป้ายภาษี ผู้ซื้อต้องรับผิดชอบคัดป้ายใหม่เอง
B27: 1013-1 | C27: Toyota | D27: Hilux Revo | E27: Single Cab | F27: J | G27: E | H27: 140000 | I27: 16000 | J27: 130000 | K27: 2019 | L27: 2ฒว-6286 | M27: กรุงเทพมหานคร | N27: 2019 | O27: 383731 | P27: RWD | Q27: 2.4 | R27: ส้ม | S27: MT | T27: ดีเซล | U27: สุวินทวงศ์
C28: หมายเหตุ: สีไม่ตรงเล่ม เนื่องจากติดสติ๊กเกอร์ ขายตามสภาพ ผู้ซื้อดำเนินการเอง บังคับโอน 2 ต่อ ค่าโอนกรรมสิทธิ์ 3000 บาท กรณีติดอายัดจราจรผู้ซื้อเป็นผู้รับผิดชอบทุกกรณี
B29: 1014 | C29: Toyota | D29: Camry | F29: HEV Premium | G29: E | H29: 635000 | I29: 18000 | J29: 754000 | K29: 2020 | L29: 1ขธ-6321 | M29: กรุงเทพมหานคร | N29: 2020 | O29: 108775 | P29: FWD | Q29: 2.5 | R29: ดำ | S29: AT | T29: ไฮบริด | U29: สุวินทวงศ์ | V29: Op-เช่า
C30: หมายเหตุ: มีค่าปรับ M-flow 660 บาท โอนกรรมสิทธิ์ผ่านผู้ขาย ค่าโอน 3000 บาท กรณีไม่มีป้ายภาษี ผู้ซื้อต้องรับผิดชอบคัดป้ายใหม่เอง
B31: 1015 | C31: Toyota | D31: Corolla Altis | F31: G | G31: C | H31: 309000 | I31: 21594 | J31: 330000 | K31: 2020 | L31: 1ขฎ-7815 | M31: กรุงเทพมหานคร | N31: 2020 | O31: 187867 | P31: FWD | Q31: 1.6 | R31: เทา | S31: AT | T31: เบนซิน | U31: สุวินทวงศ์ | V31: Op-เช่า
C32: หมายเหตุ: บังคับโอนกรรมสิทธิ์ผ่านผู้ขาย ค่าโอนกรรมสิทธิ์ 3000 บาท ค่าภาษีเรียกเก็บคืนผู้ขาย 3,594 บาท
B33: 1016 | C33: Toyota | D33: Corolla Altis | F33: G | G33: C | H33: 236000 | I33: 15000 | J33: 200000 | K33: 2018 | L33: 7กผ-8503 | M33: กรุงเทพมหานคร | N33: 2018 | O33: 98188 | P33: FWD | Q33: 1.6 | R33: เทา | S33: AT | T33: แก๊ส | U33: สุวินทวงศ์
C34: หมายเหตุ: ติดแก๊สมา ลงเล่มแล้ว ผู้ซื้อต้องทำการโอนกรรมสิทธิ์ 2 ต่อ /ผู้ซื้อต้องดำเนินการโอนภายใน 30 วัน เล่มทะเบียนชุดโอนจัดส่งภายใน 30 วัน หลังการประมูล หากเกินกำหนด ขอเอกสารใหม่ มีค่าใช้จ่าย 1,500 บาท กรณีไม่มีป้ายภาษี ผู้ซื้อต้องรับผิดชอบคัดป้ายใหม่เอง
B35: 1017 | C35: Honda | D35: City | F35: S CNG | G35: E | H35: 26000 | I35: 12100 | J35: 94000 | K35: 2013 | L35: 1กว-8133 | M35: กรุงเทพมหานคร | N35: 2013 | O35: 240877 | P35: FWD | Q35: 1.5 | R35: ขาว | S35: AT | T35: แก๊ส | U35: สุวินทวงศ์ | V35: ถูกยึดคืน
C36: หมายเหตุ: ติดแก๊สมา ลงเล่มแล้ว เอกสารหมดอายุหรือสูญหาย ขอเอกสารใหม่มีค่าใช้จ่าย 500 บาท ค่าเช็คต้น 100 บาท กรณีภาษีหมดอายุ /ไม่มีป้ายภาษี ผู้ซื้อเป็นผู้รับผิดชอบต่อภาษีและดำเนินการเอง ผู้ประมูลจะต้องโอนกรรมสิทธิ์ ภายใน 90 วัน นับจากวันที่ประมูล หากเกินระยะเวลาที่กำหนด บริษัทฯ จะไม่รับผิดชอบและไม่รับคืนรถทุกกรณี รถติดอายัดจราจร หรือ มีค่าใช้จ่ายค้างจากการใช้ทางด่วน/M-flow ผู้ซื้อเป็นผู้รับผิดชอบค่าใช้จ่ายเองทั้งหมด
B37: 1018 | C37: Suzuki | D37: Swift | F37: GA | G37: F | H37: 61000 | I37: 16100 | J37: 69000 | K37: 2013 | L37: กง-1824 | M37: สมุทรสงคราม | N37: 2013 | O37: 122433 | P37: FWD | Q37: 1.2 | R37: เทา | S37: AT | T37: เบนซิน | U37: สุวินทวงศ์ | V37: ถูกยึดคืน
